Workbook
Name Child_OverAgeRange: 'Rates Lookup'!$H$12
Name Extended_OverAgeRange: 'Rates Lookup'!$H$17
Name Rate_CH: 'Rates Lookup'!$B$62:$F$62
Name Rate_EXT: 'Rates Lookup'!$B$33:$F$43
Name Rate_MM: 'Rates Lookup'!$B$5:$F$14
Name Rate_PAR: 'Rates Lookup'!$B$48:$F$57
Name Rate_SP: 'Rates Lookup'!$B$19:$F$28

Sheet Important Notes
D2: #VALUE!
D3: Quick Guide to completing the Consolidated Funeral Product
D4: 1. Kindly ensure that you do not skip a row. 2. Policy Number is optional, only add it if you want to update a specific policy. 3. Always start with the Main Member followed by --> Spouse --> Child --> Parent --> Extended --> Beneficiary. 4. Indicate the client type (Member Type) by choosing from the list in column (B). 5. For insured lives other than the Main Member under a policy, always specify the Main Member Link ID (ID or Passport Number) in column (E). 6. Always add a member ID Number in column (F) or Passport Number in column (G). 7. Always capture a Date of Birth in column (H). 8. Benefit Name in column (J) will populate automatically based on the Member Type. 9. Indicate a Preferred Method of Communication by choosing from the list in column (AI). 10. Always add a Beneficiary for every Main Member. 11. Maximum number of lives per Member Type: a) Main Member - 1 life b) Spouse - 1 life c) Child - 6 lives (from the 7th child onwards please add them as part of the Extended member type) d) Parent - 4 lives e) Extended - 10 lives f) Beneficiaries - 6 lives 12. For Child & Extended member types, start by keying in the details of the child/member with the highest sum ccover, followed by details of the next child/member with the next highest sum cover i.e. in descending order. 13. Column AY indicates the applicable max sum cover for each member under a policy. Key in the required sum cover amount ensuring it is less than or equal to this max limit. This column also indicates if there are any errors in the details captured and will advise the type of revision that is needed.
D6: Quick Guide to completing the Consolidated Funeral Product (CFP)
D7: 1. CFP is available to the Main Member, Spouse, Child, Parent and Extended family members. 2. Funeral cover (for all Member Type) should not exceed the Main Member's Funeral cover amount, up to a maximum of: a) R150,000 per life (for Main Member and Spouse); b) R75,000 per life (for Parent and Extended where Age Next Birthday is greater than 21 years old); c) 100% of Main Member's funeral cover amount up to a max of R150,000 per life (for Child) or R75,000 per life (for Extended) where Age Next Birthday between 14 and 21 years old; d) 100% of Main Member's funeral cover amount up to a max of R50,000 per life (for Child and Extended) where Age Next Birthday between 6 and 13 years old; e) 100% of Main Member's funeral cover amount up to a max of R20,000 per life (for Child and Extended) where Age Next Birthday between 1 and 5 years old; f) R3,000 per stillborn subject to a maximum of 3 stillborns per policy - this is an automatic feature on the Main Member's cover and does not require a selection in here. 3. There is no underwriting for this product. 4. Age is derived as Age Next Birthday calculated based on the Commencement Date and Date of Birth of the member. 5. The premium for Main Member, Spouse, Parent and Extended members are calculated based on the age of the individual member. Premium for Child is a fixed rate and is calculated once for up to 6 lives. 6. VAPs are the value-added services (i.e. body repatriation, grocery, airtime, wills and tax benefits) that are compulsory (with further options) for this product at an additional fee. This is included in the Total Premium amount of the Main Member. 7. Annual increase is optional. A selection of: Option 1 --> 5% premium increase with 4% benefit increase; OR Option 2 --> 10% premium increase with 8% benefits increase are offered under this product. The selected annual increment % is applied at the policy anniversary on the premium and cover amount of all members under a policy.

Sheet Members
A1: CFP_v2 | B1: #VALUE!
A2: MEMBERS | O2: PREVIOUS INSURANCE | T2: PHYSICAL ADDRESS | Z2: POSTAL ADDRESS | AF2: COMMUNICATION | AJ2: POLICY OPTIONS | AM2: EMPLOYEE DETAILS | AQ2: BANKING DETAILS | AW2: Sales Allocation
A3: To be completed for existing policies only (optional) | B3: (select Role from list) | C3: (key in Member's Name) | E3: (key in Main Member's ID / Passport No. for all selected Roles) | F3: (key in Member's ID / Passport No.) | H3: (key in DOB in this format yyyy-mm-dd) | I3: (select Gender from list) | J3: (Benefit Name will be populated automatically based on the Member Type) -DO NOT EDIT- | K3: (key in Cover Start Date in this format yyyy-mm-dd) | L3: (can the client afford the quoted premium amount?) | M3: (premium is populated automatically) -DO NOT EDIT- | N3: (refer to column AY to know the max cover allowable) | O3: (select company name from list) | P3: (key in details) | Q3: (key in date in this format yyyy-mm-dd) | S3: (key in details) | T3: (key in Str No. & Name) | U3: (key in Suburb) | V3: (key in details) | W3: (key in details) | X3: (key in details) | Y3: (key in Area Code) | Z3: (key in P.O. Box or Private Bag) | AA3: (key in Suburb) | AB3: (key in details) | AC3: (key in details) | AD3: (key in details) | AE3: (key in Postal Code) | AF3: (key in details) | AG3: (key in details) | AH3: (key in details) | AI3: (select comm method from list) | AJ3: (select type of VAS from list) | AK3: (select Annual Increase Option from list) | AL3: (auto populated based on the month in the commencement date) -DO NOT EDIT- | AM3: (key in details) | AN3: (key in details) | AO3: (key in details) | AP3: (key in details) | AQ3: (select from list) | AR3: (select from list) | AS3: (key in details) | AT3: (key in details) | AU3: (key in details) | AV3: (key in details) | AW3: (key in details) | AY3: (shows the max cover amount allowed for each member type, based on the main member's details, product validations and regulatory requirements such as child benefit limitations) - DO NOT EDIT-
A4: Policy Number | B4: Member Type | C4: First Name | D4: Surname | E4: Main Member Link ID | F4: ID Number | G4: Passport Number | H4: Date Of Birth | I4: Gender | J4: Benefit Name | K4: Commencement Date | L4: Affordability Status | M4: Premium | N4: Cover Amount | O4: Previous Insurer | P4: Previous Insurer Policy Number | Q4: Previous Insurer Join Date | R4: Previous Insurer Cancellation Date | S4: Previous Cover Amount | T4: Address 1 | U4: Address 2 | V4: City | W4: Province | X4: Country | Y4: Area Code | Z4: Postal Address 1 | AA4: Postal Address 2 | AB4: Postal City | AC4: Postal Province | AD4: Postal Country | AE4: Postal Code | AF4: Telephone | AG4: Mobile | AH4: Email | AI4: Preferred Method Of Communication | AJ4: Product Option | AK4: Annual Increase Option | AL4: Increase Month | AM4: Employer / Payroll Code | AN4: Employer | AO4: PERSAL Number | AP4: Department | AQ4: Payment Method | AR4: Bank | AS4: Branch Code | AT4: Account# | AU4: Account Type | AV4: Debit Order Day | AW4: Representative ID | AY4: Indicative maximum Cover Amount and other validations
B5: Main Member | C5: Mae | D5: Monroe | E5: 9403175256087 | F5: 9403175256087 | H5: 34410 | I5: Female | J5: =IF(_xlfn.XLOOKUP(B5,DropdownList!$C$2:$C$8,DropdownList!$B$2:$B$8,0)=0,"",_xlfn.XLOOKUP(B5,DropdownList!$C$2:$C$8,DropdownList!$B$2:$B$8,0)) -> Consolidated Funeral - Main | K5: 46082 | L5: Affordable | M5: =IF('Onboarding Calcs'!N3=0,0,'Onboarding Calcs'!N3) -> 263.5 | N5: 120000 | T5: 56 Jorissen Street | U5: Braamfontein | V5: Johannesburg | W5: Gauteng | X5: South Africa | Y5: 2001 | Z5: 56 Jorissen Street | AA5: Braamfontein | AB5: Johannesburg | AC5: Gauteng | AD5: South Africa | AE5: 2001 | AF5: 0107843621 | AG5: 0754831572 | AH5: amuhali@randmutual.co.za | AI5: Email | AJ5: Consolidated Funeral Plus | AK5: Option 1 | AL5: =IF(OR(Table13[[#This Row],[Annual Increase Option]]="No increase",Table13[[#This Row],[Annual Increase Option]]=""),"",_xlfn.XLOOKUP(MONTH(Table13[[#This Row],[Commencement Date]]),DropdownList!$A$19:$A$30,DropdownList!$B$19:$B$30,0)) -> March | AM5: 94 | AN5: BMA | AO5: 67897899 | AP5: IT | AQ5: Debit Order | AR5: FNB | AS5: 250655 | AT5: 62398644453 | AU5: Current Account | AV5: 15 | AW5: 9305200335085 | AY5: ='Onboarding Calcs'!Q3 -> 150000
B6: Spouse | C6: Reply | D6: Monroe | E6: 9403175256087 | F6: 9403175091187 | H6: 34410 | I6: Male | J6: =IF(_xlfn.XLOOKUP(B6,DropdownList!$C$2:$C$8,DropdownList!$B$2:$B$8,0)=0,"",_xlfn.XLOOKUP(B6,DropdownList!$C$2:$C$8,DropdownList!$B$2:$B$8,0)) -> Consolidated Funeral - Spouse | K6: 46082 | M6: =IF('Onboarding Calcs'!N4=0,0,'Onboarding Calcs'!N4) -> 138.125 | N6: 100000 | AL6: =IF(OR(Table13[[#This Row],[Annual Increase Option]]="No increase",Table13[[#This Row],[Annual Increase Option]]=""),"",_xlfn.XLOOKUP(MONTH(Table13[[#This Row],[Commencement Date]]),DropdownList!$A$19:$A$30,DropdownList!$B$19:$B$30,0)) | AY6: ='Onboarding Calcs'!Q4 -> 120000
B7: Beneficiary | C7: Degal | D7: Monroe | E7: 9403175256087 | F7: 9403177609184 | H7: 34410 | I7: Male | J7: =IF(_xlfn.XLOOKUP(B7,DropdownList!$C$2:$C$8,DropdownList!$B$2:$B$8,0)=0,"",_xlfn.XLOOKUP(B7,DropdownList!$C$2:$C$8,DropdownList!$B$2:$B$8,0)) | K7: 46082 | M7: =IF('Onboarding Calcs'!N5=0,0,'Onboarding Calcs'!N5) -> 0 | N7: 100000 | AL7: =IF(OR(Table13[[#This Row],[Annual Increase Option]]="No increase",Table13[[#This Row],[Annual Increase Option]]=""),"",_xlfn.XLOOKUP(MONTH(Table13[[#This Row],[Commencement Date]]),DropdownList!$A$19:$A$30,DropdownList!$B$19:$B$30,0)) | AY7: ='Onboarding Calcs'!Q5 -> 0
B8: Beneficiary | C8: Hope | D8: Monroe | E8: 9403175256087 | F8: 9403176322086 | H8: 34410 | I8: Female | J8: =IF(_xlfn.XLOOKUP(B8,DropdownList!$C$2:$C$8,DropdownList!$B$2:$B$8,0)=0,"",_xlfn.XLOOKUP(B8,DropdownList!$C$2:$C$8,DropdownList!$B$2:$B$8,0)) | K8: 46082 | M8: =IF('Onboarding Calcs'!N6=0,0,'Onboarding Calcs'!N6) -> 0 | AL8: =IF(OR(Table13[[#This Row],[Annual Increase Option]]="No increase",Table13[[#This Row],[Annual Increase Option]]=""),"",_xlfn.XLOOKUP(MONTH(Table13[[#This Row],[Commencement Date]]),DropdownList!$A$19:$A$30,DropdownList!$B$19:$B$30,0)) | AY8: ='Onboarding Calcs'!Q6 -> 0
B9: Beneficiary | C9: Manu | D9: Thidiala | E9: 9403175256087 | F9: 9403178802085 | H9: 34410 | I9: Female | J9: =IF(_xlfn.XLOOKUP(B9,DropdownList!$C$2:$C$8,DropdownList!$B$2:$B$8,0)=0,"",_xlfn.XLOOKUP(B9,DropdownList!$C$2:$C$8,DropdownList!$B$2:$B$8,0)) | K9: 46082 | M9: =IF('Onboarding Calcs'!N7=0,0,'Onboarding Calcs'!N7) -> 0 | AL9: =IF(OR(Table13[[#This Row],[Annual Increase Option]]="No increase",Table13[[#This Row],[Annual Increase Option]]=""),"",_xlfn.XLOOKUP(MONTH(Table13[[#This Row],[Commencement Date]]),DropdownList!$A$19:$A$30,DropdownList!$B$19:$B$30,0)) | AY9: ='Onboarding Calcs'!Q7 -> 0
B10: Beneficiary | C10: Aviwe | D10: Qongqo | E10: 9403175256087 | F10: 9403175901187 | H10: 34410 | I10: Male | J10: =IF(_xlfn.XLOOKUP(B10,DropdownList!$C$2:$C$8,DropdownList!$B$2:$B$8,0)=0,"",_xlfn.XLOOKUP(B10,DropdownList!$C$2:$C$8,DropdownList!$B$2:$B$8,0)) | K10: 46082 | M10: =IF('Onboarding Calcs'!N8=0,0,'Onboarding Calcs'!N8) -> 0 | AL10: =IF(OR(Table13[[#This Row],[Annual Increase Option]]="No increase",Table13[[#This Row],[Annual Increase Option]]=""),"",_xlfn.XLOOKUP(MONTH(Table13[[#This Row],[Commencement Date]]),DropdownList!$A$19:$A$30,DropdownList!$B$19:$B$30,0)) | AY10: ='Onboarding Calcs'!Q8 -> 0
B11: Beneficiary | C11: Zwavhudi | D11: Monroe | E11: 9403175256087 | F11: 9403175519187 | H11: 34410 | I11: Female | J11: =IF(_xlfn.XLOOKUP(B11,DropdownList!$C$2:$C$8,DropdownList!$B$2:$B$8,0)=0,"",_xlfn.XLOOKUP(B11,DropdownList!$C$2:$C$8,DropdownList!$B$2:$B$8,0)) | K11: 46082 | M11: =IF('Onboarding Calcs'!N9=0,0,'Onboarding Calcs'!N9) -> 0 | AL11: =IF(OR(Table13[[#This Row],[Annual Increase Option]]="No increase",Table13[[#This Row],[Annual Increase Option]]=""),"",_xlfn.XLOOKUP(MONTH(Table13[[#This Row],[Commencement Date]]),DropdownList!$A$19:$A$30,DropdownList!$B$19:$B$30,0)) | AY11: ='Onboarding Calcs'!Q9 -> 0
J12: =IF(_xlfn.XLOOKUP(B12,DropdownList!$C$2:$C$8,DropdownList!$B$2:$B$8,0)=0,"",_xlfn.XLOOKUP(B12,DropdownList!$C$2:$C$8,DropdownList!$B$2:$B$8,0)) | M12: =IF('Onboarding Calcs'!N10=0,0,'Onboarding Calcs'!N10) -> 0 | AL12: =IF(OR(Table13[[#This Row],[Annual Increase Option]]="No increase",Table13[[#This Row],[Annual Increase Option]]=""),"",_xlfn.XLOOKUP(MONTH(Table13[[#This Row],[Commencement Date]]),DropdownList!$A$19:$A$30,DropdownList!$B$19:$B$30,0)) | AY12: ='Onboarding Calcs'!Q10 -> 0
J13: =IF(_xlfn.XLOOKUP(B13,DropdownList!$C$2:$C$8,DropdownList!$B$2:$B$8,0)=0,"",_xlfn.XLOOKUP(B13,DropdownList!$C$2:$C$8,DropdownList!$B$2:$B$8,0)) | M13: =IF('Onboarding Calcs'!N11=0,0,'Onboarding Calcs'!N11) -> 0 | AL13: =IF(OR(Table13[[#This Row],[Annual Increase Option]]="No increase",Table13[[#This Row],[Annual Increase Option]]=""),"",_xlfn.XLOOKUP(MONTH(Table13[[#This Row],[Commencement Date]]),DropdownList!$A$19:$A$30,DropdownList!$B$19:$B$30,0)) | AY13: ='Onboarding Calcs'!Q11 -> 0
J14: =IF(_xlfn.XLOOKUP(B14,DropdownList!$C$2:$C$8,DropdownList!$B$2:$B$8,0)=0,"",_xlfn.XLOOKUP(B14,DropdownList!$C$2:$C$8,DropdownList!$B$2:$B$8,0)) | M14: =IF('Onboarding Calcs'!N12=0,0,'Onboarding Calcs'!N12) -> 0 | AL14: =IF(OR(Table13[[#This Row],[Annual Increase Option]]="No increase",Table13[[#This Row],[Annual Increase Option]]=""),"",_xlfn.XLOOKUP(MONTH(Table13[[#This Row],[Commencement Date]]),DropdownList!$A$19:$A$30,DropdownList!$B$19:$B$30,0)) | AY14: ='Onboarding Calcs'!Q12 -> 0
J15: =IF(_xlfn.XLOOKUP(B15,DropdownList!$C$2:$C$8,DropdownList!$B$2:$B$8,0)=0,"",_xlfn.XLOOKUP(B15,DropdownList!$C$2:$C$8,DropdownList!$B$2:$B$8,0)) | M15: =IF('Onboarding Calcs'!N13=0,0,'Onboarding Calcs'!N13) -> 0 | AL15: =IF(OR(Table13[[#This Row],[Annual Increase Option]]="No increase",Table13[[#This Row],[Annual Increase Option]]=""),"",_xlfn.XLOOKUP(MONTH(Table13[[#This Row],[Commencement Date]]),DropdownList!$A$19:$A$30,DropdownList!$B$19:$B$30,0)) | AY15: ='Onboarding Calcs'!Q13 -> 0
J16: =IF(_xlfn.XLOOKUP(B16,DropdownList!$C$2:$C$8,DropdownList!$B$2:$B$8,0)=0,"",_xlfn.XLOOKUP(B16,DropdownList!$C$2:$C$8,DropdownList!$B$2:$B$8,0)) | M16: =IF('Onboarding Calcs'!N14=0,0,'Onboarding Calcs'!N14) -> 0 | AL16: =IF(OR(Table13[[#This Row],[Annual Increase Option]]="No increase",Table13[[#This Row],[Annual Increase Option]]=""),"",_xlfn.XLOOKUP(MONTH(Table13[[#This Row],[Commencement Date]]),DropdownList!$A$19:$A$30,DropdownList!$B$19:$B$30,0)) | AY16: ='Onboarding Calcs'!Q14 -> 0
J17: =IF(_xlfn.XLOOKUP(B17,DropdownList!$C$2:$C$8,DropdownList!$B$2:$B$8,0)=0,"",_xlfn.XLOOKUP(B17,DropdownList!$C$2:$C$8,DropdownList!$B$2:$B$8,0)) | M17: =IF('Onboarding Calcs'!N15=0,0,'Onboarding Calcs'!N15) -> 0 | AL17: =IF(OR(Table13[[#This Row],[Annual Increase Option]]="No increase",Table13[[#This Row],[Annual Increase Option]]=""),"",_xlfn.XLOOKUP(MONTH(Table13[[#This Row],[Commencement Date]]),DropdownList!$A$19:$A$30,DropdownList!$B$19:$B$30,0)) | AY17: ='Onboarding Calcs'!Q15 -> 0
J18: =IF(_xlfn.XLOOKUP(B18,DropdownList!$C$2:$C$8,DropdownList!$B$2:$B$8,0)=0,"",_xlfn.XLOOKUP(B18,DropdownList!$C$2:$C$8,DropdownList!$B$2:$B$8,0)) | M18: =IF('Onboarding Calcs'!N16=0,0,'Onboarding Calcs'!N16) -> 0 | AL18: =IF(OR(Table13[[#This Row],[Annual Increase Option]]="No increase",Table13[[#This Row],[Annual Increase Option]]=""),"",_xlfn.XLOOKUP(MONTH(Table13[[#This Row],[Commencement Date]]),DropdownList!$A$19:$A$30,DropdownList!$B$19:$B$30,0)) | AY18: ='Onboarding Calcs'!Q16 -> 0
J19: =IF(_xlfn.XLOOKUP(B19,DropdownList!$C$2:$C$8,DropdownList!$B$2:$B$8,0)=0,"",_xlfn.XLOOKUP(B19,DropdownList!$C$2:$C$8,DropdownList!$B$2:$B$8,0)) | M19: =IF('Onboarding Calcs'!N17=0,0,'Onboarding Calcs'!N17) -> 0 | AL19: =IF(OR(Table13[[#This Row],[Annual Increase Option]]="No increase",Table13[[#This Row],[Annual Increase Option]]=""),"",_xlfn.XLOOKUP(MONTH(Table13[[#This Row],[Commencement Date]]),DropdownList!$A$19:$A$30,DropdownList!$B$19:$B$30,0)) | AY19: ='Onboarding Calcs'!Q17 -> 0
J20: =IF(_xlfn.XLOOKUP(B20,DropdownList!$C$2:$C$8,DropdownList!$B$2:$B$8,0)=0,"",_xlfn.XLOOKUP(B20,DropdownList!$C$2:$C$8,DropdownList!$B$2:$B$8,0)) | M20: =IF('Onboarding Calcs'!N18=0,0,'Onboarding Calcs'!N18) -> 0 | AL20: =IF(OR(Table13[[#This Row],[Annual Increase Option]]="No increase",Table13[[#This Row],[Annual Increase Option]]=""),"",_xlfn.XLOOKUP(MONTH(Table13[[#This Row],[Commencement Date]]),DropdownList!$A$19:$A$30,DropdownList!$B$19:$B$30,0)) | AY20: ='Onboarding Calcs'!Q18 -> 0
J21: =IF(_xlfn.XLOOKUP(B21,DropdownList!$C$2:$C$8,DropdownList!$B$2:$B$8,0)=0,"",_xlfn.XLOOKUP(B21,DropdownList!$C$2:$C$8,DropdownList!$B$2:$B$8,0)) | M21: =IF('Onboarding Calcs'!N19=0,0,'Onboarding Calcs'!N19) -> 0 | AL21: =IF(OR(Table13[[#This Row],[Annual Increase Option]]="No increase",Table13[[#This Row],[Annual Increase Option]]=""),"",_xlfn.XLOOKUP(MONTH(Table13[[#This Row],[Commencement Date]]),DropdownList!$A$19:$A$30,DropdownList!$B$19:$B$30,0)) | AY21: ='Onboarding Calcs'!Q19 -> 0
J23: =IF(_xlfn.XLOOKUP(B23,DropdownList!$C$2:$C$8,DropdownList!$B$2:$B$8,0)=0,"",_xlfn.XLOOKUP(B23,DropdownList!$C$2:$C$8,DropdownList!$B$2:$B$8,0)) | M23: =IF('Onboarding Calcs'!N20=0,0,'Onboarding Calcs'!N20) -> 0 | AL23: =IF(OR(Table13[[#This Row],[Annual Increase Option]]="No increase",Table13[[#This Row],[Annual Increase Option]]=""),"",_xlfn.XLOOKUP(MONTH(Table13[[#This Row],[Commencement Date]]),DropdownList!$A$19:$A$30,DropdownList!$B$19:$B$30,0)) | AY23: ='Onboarding Calcs'!Q20 -> 0
J24: =IF(_xlfn.XLOOKUP(B24,DropdownList!$C$2:$C$8,DropdownList!$B$2:$B$8,0)=0,"",_xlfn.XLOOKUP(B24,DropdownList!$C$2:$C$8,DropdownList!$B$2:$B$8,0)) | M24: =IF('Onboarding Calcs'!N21=0,0,'Onboarding Calcs'!N21) -> 0 | AL24: =IF(OR(Table13[[#This Row],[Annual Increase Option]]="No increase",Table13[[#This Row],[Annual Increase Option]]=""),"",_xlfn.XLOOKUP(MONTH(Table13[[#This Row],[Commencement Date]]),DropdownList!$A$19:$A$30,DropdownList!$B$19:$B$30,0)) | AY24: ='Onboarding Calcs'!Q21 -> 0
J25: =IF(_xlfn.XLOOKUP(B25,DropdownList!$C$2:$C$8,DropdownList!$B$2:$B$8,0)=0,"",_xlfn.XLOOKUP(B25,DropdownList!$C$2:$C$8,DropdownList!$B$2:$B$8,0)) | M25: =IF('Onboarding Calcs'!N22=0,0,'Onboarding Calcs'!N22) -> 0 | AL25: =IF(OR(Table13[[#This Row],[Annual Increase Option]]="No increase",Table13[[#This Row],[Annual Increase Option]]=""),"",_xlfn.XLOOKUP(MONTH(Table13[[#This Row],[Commencement Date]]),DropdownList!$A$19:$A$30,DropdownList!$B$19:$B$30,0)) | AY25: ='Onboarding Calcs'!Q22 -> 0
J26: =IF(_xlfn.XLOOKUP(B26,DropdownList!$C$2:$C$8,DropdownList!$B$2:$B$8,0)=0,"",_xlfn.XLOOKUP(B26,DropdownList!$C$2:$C$8,DropdownList!$B$2:$B$8,0)) | M26: =IF('Onboarding Calcs'!N23=0,0,'Onboarding Calcs'!N23) -> 0 | AL26: =IF(OR(Table13[[#This Row],[Annual Increase Option]]="No increase",Table13[[#This Row],[Annual Increase Option]]=""),"",_xlfn.XLOOKUP(MONTH(Table13[[#This Row],[Commencement Date]]),DropdownList!$A$19:$A$30,DropdownList!$B$19:$B$30,0)) | AY26: ='Onboarding Calcs'!Q23 -> 0
J27: =IF(_xlfn.XLOOKUP(B27,DropdownList!$C$2:$C$8,DropdownList!$B$2:$B$8,0)=0,"",_xlfn.XLOOKUP(B27,DropdownList!$C$2:$C$8,DropdownList!$B$2:$B$8,0)) | M27: =IF('Onboarding Calcs'!N24=0,0,'Onboarding Calcs'!N24) -> 0 | AL27: =IF(OR(Table13[[#This Row],[Annual Increase Option]]="No increase",Table13[[#This Row],[Annual Increase Option]]=""),"",_xlfn.XLOOKUP(MONTH(Table13[[#This Row],[Commencement Date]]),DropdownList!$A$19:$A$30,DropdownList!$B$19:$B$30,0)) | AY27: ='Onboarding Calcs'!Q24 -> 0
J28: =IF(_xlfn.XLOOKUP(B28,DropdownList!$C$2:$C$8,DropdownList!$B$2:$B$8,0)=0,"",_xlfn.XLOOKUP(B28,DropdownList!$C$2:$C$8,DropdownList!$B$2:$B$8,0)) | M28: =IF('Onboarding Calcs'!N25=0,0,'Onboarding Calcs'!N25) -> 0 | AL28: =IF(OR(Table13[[#This Row],[Annual Increase Option]]="No increase",Table13[[#This Row],[Annual Increase Option]]=""),"",_xlfn.XLOOKUP(MONTH(Table13[[#This Row],[Commencement Date]]),DropdownList!$A$19:$A$30,DropdownList!$B$19:$B$30,0)) | AY28: ='Onboarding Calcs'!Q25 -> 0
J29: =IF(_xlfn.XLOOKUP(B29,DropdownList!$C$2:$C$8,DropdownList!$B$2:$B$8,0)=0,"",_xlfn.XLOOKUP(B29,DropdownList!$C$2:$C$8,DropdownList!$B$2:$B$8,0)) | M29: =IF('Onboarding Calcs'!N26=0,0,'Onboarding Calcs'!N26) -> 0 | AL29: =IF(OR(Table13[[#This Row],[Annual Increase Option]]="No increase",Table13[[#This Row],[Annual Increase Option]]=""),"",_xlfn.XLOOKUP(MONTH(Table13[[#This Row],[Commencement Date]]),DropdownList!$A$19:$A$30,DropdownList!$B$19:$B$30,0)) | AY29: ='Onboarding Calcs'!Q26 -> 0
J30: =IF(_xlfn.XLOOKUP(B30,DropdownList!$C$2:$C$8,DropdownList!$B$2:$B$8,0)=0,"",_xlfn.XLOOKUP(B30,DropdownList!$C$2:$C$8,DropdownList!$B$2:$B$8,0)) | M30: =IF('Onboarding Calcs'!N27=0,0,'Onboarding Calcs'!N27) -> 0 | AL30: =IF(OR(Table13[[#This Row],[Annual Increase Option]]="No increase",Table13[[#This Row],[Annual Increase Option]]=""),"",_xlfn.XLOOKUP(MONTH(Table13[[#This Row],[Commencement Date]]),DropdownList!$A$19:$A$30,DropdownList!$B$19:$B$30,0)) | AY30: ='Onboarding Calcs'!Q27 -> 0
J31: =IF(_xlfn.XLOOKUP(B31,DropdownList!$C$2:$C$8,DropdownList!$B$2:$B$8,0)=0,"",_xlfn.XLOOKUP(B31,DropdownList!$C$2:$C$8,DropdownList!$B$2:$B$8,0)) | M31: =IF('Onboarding Calcs'!N28=0,0,'Onboarding Calcs'!N28) -> 0 | AL31: =IF(OR(Table13[[#This Row],[Annual Increase Option]]="No increase",Table13[[#This Row],[Annual Increase Option]]=""),"",_xlfn.XLOOKUP(MONTH(Table13[[#This Row],[Commencement Date]]),DropdownList!$A$19:$A$30,DropdownList!$B$19:$B$30,0)) | AY31: ='Onboarding Calcs'!Q28 -> 0
J32: =IF(_xlfn.XLOOKUP(B32,DropdownList!$C$2:$C$8,DropdownList!$B$2:$B$8,0)=0,"",_xlfn.XLOOKUP(B32,DropdownList!$C$2:$C$8,DropdownList!$B$2:$B$8,0)) | M32: =IF('Onboarding Calcs'!N29=0,0,'Onboarding Calcs'!N29) -> 0 | AL32: =IF(OR(Table13[[#This Row],[Annual Increase Option]]="No increase",Table13[[#This Row],[Annual Increase Option]]=""),"",_xlfn.XLOOKUP(MONTH(Table13[[#This Row],[Commencement Date]]),DropdownList!$A$19:$A$30,DropdownList!$B$19:$B$30,0)) | AY32: ='Onboarding Calcs'!Q29 -> 0
J33: =IF(_xlfn.XLOOKUP(B33,DropdownList!$C$2:$C$8,DropdownList!$B$2:$B$8,0)=0,"",_xlfn.XLOOKUP(B33,DropdownList!$C$2:$C$8,DropdownList!$B$2:$B$8,0)) | M33: =IF('Onboarding Calcs'!N30=0,0,'Onboarding Calcs'!N30) -> 0 | AL33: =IF(OR(Table13[[#This Row],[Annual Increase Option]]="No increase",Table13[[#This Row],[Annual Increase Option]]=""),"",_xlfn.XLOOKUP(MONTH(Table13[[#This Row],[Commencement Date]]),DropdownList!$A$19:$A$30,DropdownList!$B$19:$B$30,0)) | AY33: ='Onboarding Calcs'!Q30 -> 0
J34: =IF(_xlfn.XLOOKUP(B34,DropdownList!$C$2:$C$8,DropdownList!$B$2:$B$8,0)=0,"",_xlfn.XLOOKUP(B34,DropdownList!$C$2:$C$8,DropdownList!$B$2:$B$8,0)) | M34: =IF('Onboarding Calcs'!N31=0,0,'Onboarding Calcs'!N31) -> 0 | AL34: =IF(OR(Table13[[#This Row],[Annual Increase Option]]="No increase",Table13[[#This Row],[Annual Increase Option]]=""),"",_xlfn.XLOOKUP(MONTH(Table13[[#This Row],[Commencement Date]]),DropdownList!$A$19:$A$30,DropdownList!$B$19:$B$30,0)) | AY34: ='Onboarding Calcs'!Q31 -> 0
... J101: =IF(_xlfn.XLOOKUP(B101,DropdownList!$C$2:$C$8,DropdownList!$B$2:$B$8,0)=0,"",_xlfn.XLOOKUP(B101,DropdownList!$C$2:$C$8,DropdownList!$B$2:$B$8,0)) | M101: =IF('Onboarding Calcs'!N98=0,0,'Onboarding Calcs'!N98) -> 0 | AL101: =IF(OR(Table13[[#This Row],[Annual Increase Option]]="No increase",Table13[[#This Row],[Annual Increase Option]]=""),"",_xlfn.XLOOKUP(MONTH(Table13[[#This Row],[Commencement Date]]),DropdownList!$A$19:$A$30,DropdownList!$B$19:$B$30,0)) | AY101: ='Onboarding Calcs'!Q98 -> 0

Sheet DropdownList
A1: Roles | B1: Benefits | C1: Roles | D1: Communication | E1: Annual Increase Option | F1: Binary Choice | G1: Month | H1: Banks | I1: Account Type | J1: Previous Insurer | K1: Gender | L1: Affordability | M1: Product Option | N1: Payment Method | O1: VAS Premium | P1: Version No | Q1: Version Date
P2: CFP_v2 | Q2: 46011
A3: Main Member | B3: Consolidated Funeral - Main | C3: Main Member | D3: Email | E3: No increase | F3: Yes | G3: January | H3: ABSA | I3: Cheque Account | J3: African Unity Life | K3: Female | L3: Affordable | M3: Consolidated Funeral Basic | N3: Corporate Stop Order | O3: 1.53 | P3: Validity | Q3: =MAX(Q2,TODAY())+90 -> 46313
A4: Spouse | B4: Consolidated Funeral - Spouse | C4: Spouse | D4: SMS | E4: Option 1 | F4: No | G4: February | H4: AFRICAN BANK | I4: Credit Card Account | J4: Alexander Forbes | K4: Male | L4: Not Affordable | M4: Consolidated Funeral Plus | N4: Debit Order | O4: 7.6
A5: Child | B5: Consolidated Funeral - Child | C5: Child | D5: Post | E5: Option 2 | G5: March | H5: BIDVEST BANK | I5: Current Account | J5: Assupol | N5: Government Salary Deduction
A6: Parent | B6: Consolidated Funeral - Parents | C6: Parent | G6: April | H6: CAPITEC | I6: Savings Account | J6: Brightrock Life Limited
A7: Extended | B7: Consolidated Funeral - Extended | C7: Extended | E7: Annual increase option | G7: May | H7: DISCOVERY BANK LTD | I7: Transmission Account | J7: Centriq Life Insurance
A8: Beneficiary | C8: Beneficiary | E8: None | G8: June | H8: FNB | J8: Clientele
E9: 5% premium increase with 4% benefit increase | G9: July | H9: ITHALA BANK | J9: Dignity Group
E10: 10% premium increase with 8% benefits increase | G10: August | H10: NEDBANK | J10: Ditiro Group Funeral Administrator
G11: September | H11: OLD MUTUAL BANK | J11: Hollard Life
G12: October | H12: POST BANK | J12: KGA Life
G13: November | H13: STANDARD BANK | J13: Liberty
G14: December | H14: TYMEBANK | J14: Merritt Administrators
H15: UBANK | J15: Metropolitan
H16: VBS MUTUAL BANK | J16: Old Mutual
J17: Old Mutual Life Assurance Company
A18: Increase Option | J18: Prosper Funeral Solutions
A19: 1 | B19: January | J19: Safrican Insurance Company
A20: 2 | B20: February | J20: Sanlam
A21: 3 | B21: March | J21: Santam
A22: 4 | B22: April
A23: 5 | B23: May
A24: 6 | B24: June
A25: 7 | B25: July
A26: 8 | B26: August
A27: 9 | B27: September
A28: 10 | B28: October
A29: 11 | B29: November
A30: 12 | B30: December

Sheet Rates Lookup
B1: Premium Rates
I2: The Lower of % of MM Sum Cover OR Max Amount
B3: MAIN MEMBER | E3: SUM ASSURED | H3: Max Sum Cover | I3: As a % of MM Sum Cover | J3: As a Max Amount
B4: AGE FROM | C4: AGE TO | D4: INDEX | E4: FIXED AMT | F4: RATE PER R10,000 | H4: Main Member | I4: 1 | J4: 150000
B5: 18 | C5: 25 | D5: 2 | E5: 97.75 | F5: 5.355 | H5: Spouse | I5: 1 | J5: 150000
B6: 26 | C6: 35 | D6: 3 | E6: 97.75 | F6: 9.69 | H6: Extended | I6: 1 | J6: 75000
B7: 36 | C7: 45 | D7: 4 | E7: 97.75 | F7: 13.8125 | H7: Parent | I7: 1 | J7: 75000
B8: 46 | C8: 50 | D8: 5 | E8: 97.75 | F8: 14.195 | H8: Child
B9: 51 | C9: 55 | D9: 6 | E9: 97.75 | F9: 14.45 | H9: 1 | I9: 1 | J9: 20000
B10: 56 | C10: 60 | D10: 7 | E10: 97.75 | F10: 15.47 | H10: 6 | I10: 1 | J10: 50000
B11: 61 | C11: 65 | D11: 8 | E11: 97.75 | F11: 17.935 | H11: 14 | I11: 1 | J11: 150000
B12: 66 | C12: 70 | D12: 9 | E12: 97.75 | F12: 26.605 | H12: 22 | I12: 0 | J12: 0
B13: 71 | C13: 75 | D13: 10 | E13: 97.75 | F13: 45.475 | H13: Extended
B14: 76 | C14: 99999 | D14: 11 | E14: 0 | F14: 0 | H14: 1 | I14: 1 | J14: 20000
H15: 6 | I15: 1 | J15: 50000
H16: 14 | I16: 1 | J16: 75000
B17: SPOUSE | E17: SUM ASSURED | H17: 22 | I17: 1 | J17: 75000
B18: AGE FROM | C18: AGE TO | D18: INDEX | E18: FIXED EXP | F18: RATE PER R10000
B19: 18 | C19: 25 | D19: 2 | E19: 0 | F19: 5.355
B20: 26 | C20: 35 | D20: 3 | E20: 0 | F20: 9.69
B21: 36 | C21: 45 | D21: 4 | E21: 0 | F21: 13.8125
B22: 46 | C22: 50 | D22: 5 | E22: 0 | F22: 14.195
B23: 51 | C23: 55 | D23: 6 | E23: 0 | F23: 14.45
B24: 56 | C24: 60 | D24: 7 | E24: 0 | F24: 15.47
B25: 61 | C25: 65 | D25: 8 | E25: 0 | F25: 17.935
B26: 66 | C26: 70 | D26: 9 | E26: 0 | F26: 26.605
B27: 71 | C27: 75 | D27: 10 | E27: 0 | F27: 45.475
B28: 76 | C28: 99999 | D28: 11 | E28: 0 | F28: 0
B31: EXTENDED FAMILY | E31: SUM ASSURED
B32: AGE FROM | C32: AGE TO | D32: INDEX | E32: FIXED EXP | F32: RATE PER R10000
B33: 1 | C33: 20 | D33: 2 | E33: 0 | F33: 5.525
B34: 21 | C34: 25 | D34: 3 | E34: 0 | F34: 11.05
B35: 26 | C35: 35 | D35: 4 | E35: 0 | F35: 21.25
B36: 36 | C36: 45 | D36: 5 | E36: 0 | F36: 29.75
B37: 46 | C37: 50 | D37: 6 | E37: 0 | F37: 30.6
B38: 51 | C38: 55 | D38: 7 | E38: 0 | F38: 33.15
B39: 56 | C39: 60 | D39: 8 | E39: 0 | F39: 40.8
B40: 61 | C40: 65 | D40: 9 | E40: 0 | F40: 59.5
B41: 66 | C41: 70 | D41: 10 | E41: 0 | F41: 90.95
B42: 71 | C42: 75 | D42: 11 | E42: 0 | F42: 144.5
...

Sheet Quotation Tool
C3: Consolidated Funeral Product (CFP_v2) Quotation Tool
D5: Important Quoting Notes
C6: 1 | D6: Insert date in this format: DD/MM/YYYY | I6: #VALUE!
C7: 2 | D7: Cover Type | E7: Member Type | G7: Maximum Cover Amount
D8: Funeral Cover (per life) | E8: Main Member | G8: 150000
E9: Spouse | G9: R150,000 or Main Member funeral cover amount, whichever is lower
E10: Child and Extended (of Age Next Birthday between 1 and 5 years old) | G10: R20,000 or Main Member funeral cover amount, whichever is lower
E11: Child and Extended (of Age Next Birthday between 6 and 13 years old) | G11: R50,000 or Main Member funeral cover amount, whichever is lower
E12: Child (of Age Next Birthday between 14 and 21 years old) | G12: R150,000 or Main Member funeral cover amount, whichever is lower
E13: Extended (of Age Next Birthday between 14 and 21 years old) | G13: R75,000 or Main Member funeral cover amount, whichever is lower
E14: Parent and Extended (of Age Next Birthday greater than 21 years old) | G14: R75,000 or Main Member funeral cover amount, whichever is lower
E15: Stillborn Child | G15: R3,000 per stillborn subject to a maximum of 3 stillborns per policy (automatic benefit feature)
C16: 3 | D16: The funeral cover amount for Spouse, Child, Extended or Parent cannot exceed the funeral cover amount of the Main Member
C17: 4 | D17: Age is derived as Age Next Birthday calculated based on the Commencement Date and Date of Birth of the member.
C18: 5 | D18: The premium for Main Member, Spouse, Parent and Extended members are calculated based on the age of the individual member.
D19: Premium for Child is a fixed rate and is calculated once for up to 6 lives.
C20: 6 | D20: How to Use this Tool | E20: Input cell | G20: Clear out any values in this cell before starting a quote
E21: Select from Drop Down List
E22: Indicative cell <Do not Edit>
E23: Premium calculation cell <Do not Edit>
E24: Final output cell <Do not Edit>
D27: Commencement date
D28: 46113
D30: Product Option | H30: VAS Amount (EuropAssist)
D31: VAS benefit selected | E31: Consolidated Funeral Basic | H31: Compulsory benefits only (Basic plan) | K31: 1.53
D32: Annual increase option | E32: 5% premium increase with 4% benefit increase | H32: Additional Optional benefits | K32: 7.6
H33: Plus plan includes both compulsory and optional benefits. VAS amount for this chosen plan will be a total of R 9.13
D35: FUNERAL COVER (Main Member & Spouse) | E35: Date of Birth | F35: Age Next Birthday (ANB) | G35: Max Cover Amount | H35: Cover Amount | I35: Fixed rate | J35: Rate per R10,000 | K35: Quoted Premium Amount
D36: Main Member | E36: 34678 | F36: 32 | G36: =IF(OR(F36="",F36=0),0,150000) -> 150000 | H36: 150000 | I36: =IFERROR(VLOOKUP($F36,Rate_MM,4),0) -> 97.75 | J36: =IFERROR(VLOOKUP($F36,Rate_MM,5),0) -> 9.69 | K36: =IF(H36<=G36,IFERROR(I36+H36/10000*J36,0),0) -> 243.1
D37: Spouse | E37: 14-06-1995 | F37: 31 | G37: =IF(OR(F37="",F37=0),0,IF($H$36="",0,$H$36)) -> 150000 | H37: 150000 | I37: Not applicable | J37: =IFERROR(VLOOKUP($F37,Rate_SP,5),0) -> 9.69 | K37: =IF(H37<=G37,IFERROR(H37/10000*J37,0),0) -> 145.35
D39: FUNERAL COVER (Child) | E39: Date of Birth | F39: ANB - Child | G39: Max Cover Amount | H39: Cover Amount | I39: Fixed rate | J39: Rate per R10,000 | K39: Quoted Premium Amount
D40: Child 1 | E40: 01-01-2013 | F40: 14 | G40: =IF(OR(F40="",F40=0),0,MIN(VLOOKUP(F40,'Rates Lookup'!$H$9:$J$12,3),IF($H$36="",0,$H$36))) -> 150000 | H40: 150000 | I40: Not applicable | J40: =IFERROR(VLOOKUP($F40,Rate_CH,5),0) -> 6.97 | K40: =IF(MAX($H$40:$H$45)<=MAX($G$40:$G$45),IFERROR(MAX($H$40:$H$45)/10000*J40,0),0) -> 104.55
D41: Child 2 | G41: =IF(OR(F41="",F41=0),0,MIN(VLOOKUP(F41,'Rates Lookup'!$H$9:$J$12,3),IF($H$36="",0,$H$36))) -> 0
D42: Child 3 | G42: =IF(OR(F42="",F42=0),0,MIN(VLOOKUP(F42,'Rates Lookup'!$H$9:$J$12,3),IF($H$36="",0,$H$36))) -> 0
D43: Child 4 | G43: =IF(OR(F43="",F43=0),0,MIN(VLOOKUP(F43,'Rates Lookup'!$H$9:$J$12,3),IF($H$36="",0,$H$36))) -> 0
D44: Child 5 | G44: =IF(OR(F44="",F44=0),0,MIN(VLOOKUP(F44,'Rates Lookup'!$H$9:$J$12,3),IF($H$36="",0,$H$36))) -> 0
D45: Child 6 | G45: =IF(OR(F45="",F45=0),0,MIN(VLOOKUP(F45,'Rates Lookup'!$H$9:$J$12,3),IF($H$36="",0,$H$36))) -> 0
D47: FUNERAL COVER (Parents) | E47: Date of Birth | F47: ANB - Parents | G47: Max Cover Amount | H47: Cover Amount | I47: Fixed rate | J47: Rate per R10,000 | K47: Quoted Premium Amount
D48: Parent 1 | E48: 21-01-1988 | F48: 39 | G48: =IF(OR(F48="",F48=0),0,MIN(75000,IF($H$36="",0,$H$36))) -> 75000 | H48: 75000 | I48: Not applicable | J48: =IFERROR(VLOOKUP($F48,Rate_PAR,5),0) -> 23.8 | K48: =IF(H48<=G48,IFERROR(H48/10000*J48,0),0) -> 178.5
D49: Parent 2 | G49: =IF(OR(F49="",F49=0),0,MIN(75000,IF($H$36="",0,$H$36))) -> 0 | I49: Not applicable | J49: =IFERROR(VLOOKUP($F49,Rate_PAR,5),0) -> 0 | K49: =IF(H49<=G49,IFERROR(H49/10000*J49,0),0) -> 0
...

Sheet Onboarding Calcs
B2: Member Type | C2: Main Member Link ID | D2: ID Number | E2: Passport Number | F2: Date Of Birth | G2: Gender | H2: Benefit Name | I2: Commencement Date | J2: Age | K2: Rate per 10,000 | L2: Fixed Rate | M2: Cover Amount | N2: Premium to Show | O2: Indicative Max Sum Cover for each Member Type | P2: Count of Member Type | Q2: Error Message to Show | R2: Each Child Premium | S2: No. of Child with same Cover Amont under a policy | T2: Is Child Sum Cover Highest? | U2: Allocation of Child Premium
B3: =Members!B5 -> Main Member | C3: =Members!E5 -> 9403175256087 | D3: =Members!F5 -> 9403175256087 | E3: =Members!G5 -> 0 | F3: =Members!H5 -> 32706 | G3: =Members!I5 -> Female | H3: =Members!J5 -> Consolidated Funeral - Main | I3: =Members!K5 -> 46082 | J3: =IFERROR(DATEDIF(F3,I3,"Y")+1,0) -> 37 | K3: =IFERROR(IF(OR(B3=0,Table3[[#This Row],[Age]]=0,Table3[[#This Row],[Member Type]]="Beneficiary"),0, IF(B3="Main Member",VLOOKUP(J3,Rate_MM,5), IF(B3="Spouse",VLOOKUP(J3,Rate_SP,5), IF(B3="Extended",VLOOKUP(J3,Rate_EXT,5), IF(B3="Parent",VLOOKUP(J3,Rate_PAR,5), IF(B3="Child",VLOOKUP(J3,Rate_CH,5))))))),0) -> 13.8125 | L3: =IFERROR(IF(OR(B3=0,Table3[[#This Row],[Age]]=0,Table3[[#This Row],[Member Type]]="Beneficiary"),0, IF(B3="Main Member",VLOOKUP(J3,Rate_MM,4), IF(B3="Spouse",VLOOKUP(J3,Rate_SP,4), IF(B3="Extended",VLOOKUP(J3,Rate_EXT,4), IF(B3="Parent",VLOOKUP(J3,Rate_PAR,4), IF(B3="Child",VLOOKUP(J3,Rate_CH,4))))))),0) -> 97.75 | M3: =Members!N5 -> 120000 | N3: =IF(Table3[[#This Row],[Member Type]]<>"Child",Table3[[#This Row],[Rate per 10,000]]/10000*Table3[[#This Row],[Cover Amount]]+IF(Table3[[#This Row],[Cover Amount]]>0,Table3[[#This Row],[Fixed Rate]],0), IF(AND(Table3[[#This Row],[Member Type]]="Child",Table3[[#This Row],[Count of Member Type]]>6),0,Table3[[#This Row],[Each Child Premium]]*Table3[[#This Row],[Allocation of Child Premium]]+IF(Table3[[#This Row],[Cover Amount]]>0,Table3[[#This Row],[Fixed Rate]],0))) -> 263.5 | O3: =IF(Table3[[#This Row],[Member Type]]=0,0, IF(AND(Table3[[#This Row],[Member Type]]="Child",Table3[[#This Row],[Count of Member Type]]>6),-1, IF(AND(Table3[[#This Row],[Member Type]]="Extended",Table3[[#This Row],[Count of Member Type]]>10),-2, IF(AND(Table3[[#This Row],[Member Type]]="Parent",Table3[[#This Row],[Count of Member Type]]>4),-3, IF(AND(Table3[[#This Row],[Member Type]]="Beneficiary",Table3[[#This Row],[Count of Member Type]]>6),-4, IF(AND(Table3[[#This Row],[Member Type]]="Beneficiary",Table3[[#This Row],[Count of Member Type]]<=6),0, IF(OR(Table3[[#This Row],[Age]]>75,Table3[[#This Row],[Age]]="#NUM!"),-6, IFERROR( IF(AND(Table3[[#This Row],[Age]]<Child_OverAgeRange,Table3[[#This Row],[Member Type]]="Child"), MIN(VLOOKUP(Table3[[#This Row],[Age]],'Rates Lookup'!$H$9:$J$12,3,TRUE),VLOOKUP(Table3[[#This Row],[Age]],'Rates Lookup'!$H$9:$J$12,2,TRUE)*_xlfn.XLOOKUP(Table3[[#This Row],[Main Member Link ID]],Table3[Main Member Link ID],Table3[Cover Amount],0)), IF(AND(Table3[[#This Row],[Age]]>=Child_OverAgeRange,Table3[[#This Row],[Member Type]]="Child"),-5, IF(AND(Table3[[#This Row],[Age]]<Extended_OverAgeRange,Table3[[#This Row],[Member Type]]="Extended"), MIN(VLOOKUP(Table3[[#This Row],[Age]],'Rates Lookup'!$H$14:$J$17,3,TRUE),VLOOKUP(Table3[[#This Row],[Age]],'Rates Lookup'!$H$14:$J$17,2,TRUE)*_xlfn.XLOOKUP(Table3[[#This Row],[Main Member Link ID]],Table3[Main Member Link ID],Table3[Cover Amount],0)), IF(AND(Table3[[#This Row],[Age]]>=Extended_OverAgeRange,Table3[[#This Row],[Member Type]]="Extended"), MIN(VLOOKUP(Table3[[#This Row],[Age]],'Rates Lookup'!$H$14:$J$17,3,TRUE),VLOOKUP(Table3[[#This Row],[Age]],'Rates Lookup'!$H$14:$J$17,2,TRUE)*_xlfn.XLOOKUP(Table3[[#This Row],[Main Member Link ID]],Table3[Main Member Link ID],Table3[Cover Amount],0)), IF(Table3[[#This Row],[Member Type]]="Main Member",VLOOKUP(Table3[[#This Row],[Member Type]],'Rates Lookup'!$H$4:$J$17,3,FALSE), IF(OR(Table3[[#This Row],[Member Type]]="Spouse",Table3[[#This Row],[Member Type]]="Parent"),MIN(VLOOKUP(Table3[[#This Row],[Member Type]],'Rates Lookup'!$H$4:$J$17,3,FALSE),VLOOKUP(Table3[[#This Row],[Member Type]],'Rates Lookup'!$H$4:$J$17,2,FALSE)*_xlfn.XLOOKUP(Table3[[#This Row],[Main Member Link ID]],Table3[Main Member Link ID],Table3[Cover Amount],0)))))))),-6)))))))) -> 150000 | P3: =IF(Table3[[#This Row],[Member Type]]="Child",COUNTIFS($B$3:$B$98,"Child",$C$3:$C$98,Table3[[#This Row],[Main Member Link ID]])-COUNTIFS($B4:$B$98,"Child",$C4:$C$98,Table3[[#This Row],[Main Member Link ID]]), IF(Table3[[#This Row],[Member Type]]="Extended",COUNTIFS($B$3:$B$98,"Extended",$C$3:$C$98,Table3[[#This Row],[Main Member Link ID]])-COUNTIFS($B4:$B$98,"Extended",$C4:$C$98,Table3[[#This Row],[Main Member Link ID]]), IF(Table3[[#This Row],[Member Type]]="Parent",COUNTIFS($B$3:$B$98,"Parent",$C$3:$C$98,Table3[[#This Row],[Main Member Link ID]])-COUNTIFS($B4:$B$98,"Parent",$C4:$C$98,Table3[[#This Row],[Main Member Link ID]]), IF(Table3[[#This Row],[Member Type]]="Spouse",COUNTIFS($B$3:$B$98,"Spouse",$C$3:$C$98,Table3[[#This Row],[Main Member Link ID]])-COUNTIFS($B4:$B$98,"Spouse",$C4:$C$98,Table3[[#This Row],[Main Member Link ID]]), IF(Table3[[#This Row],[Member Type]]="Main Member",COUNTIFS($B$3:$B$98,"Main Member",$C$3:$C$98,Table3[[#This Row],[Main Member Link ID]])-COUNTIFS($B4:$B$98,"Main Member",$C4:$C$98,Table3[[#This Row],[Main Member Link ID]]), IF(Table3[[#This Row],[Member Type]]="Beneficiary",COUNTIFS($B$3:$B$98,"Beneficiary",$C$3:$C$98,Table3[[#This Row],[Main Member Link ID]])-COUNTIFS($B4:$B$98,"Beneficiary",$C4:$C$98,Table3[[#This Row],[Main Member Link ID]]),0)))))) -> 1 | Q3: =IF(Table3[[#This Row],[Indicative Max Sum Cover for each Member Type]]=-1,"Exceeded number of lives allowed for Child member type", IF(Table3[[#This Row],[Indicative Max Sum Cover for each Member Type]]=-2,"Exceeded number of lives allowed for Extended member type", IF(Table3[[#This Row],[Indicative Max Sum Cover for each Member Type]]=-3,"Exceeded number of lives allowed for Parent member type", IF(Table3[[#This Row],[Indicative Max Sum Cover for each Member Type]]=-4,"Exceeded number of lives allowed for Beneficiary member type", IF(Table3[[#This Row],[Indicative Max Sum Cover for each Member Type]]=-5,"Change to Extended member type", IF(Table3[[#This Row],[Indicative Max Sum Cover for each Member Type]]=-6,"Check Member Type or Date of Birth",Table3[[#This Row],[Indicative Max Sum Cover for each Member Type]])))))) -> 150000 | R3: =IF(Table3[[#This Row],[Member Type]]="Child",Table3[[#This Row],[Rate per 10,000]]/10000*Table3[[#This Row],[Cover Amount]],0) -> 0 | S3: =IF(Table3[[#This Row],[Member Type]]="Child",COUNTIFS(Table3[Each Child Premium],Table3[[#This Row],[Each Child Premium]],Table3[Main Member Link ID],Table3[[#This Row],[Main Member Link ID]]),0) -> 0 | T3: =IF(Table3[[#This Row],[No. of Child with same Cover Amont under a policy]]=0,"",IF(Table3[[#This Row],[Each Child Premium]]>=_xlfn.MAXIFS(Table3[Each Child Premium],Table3[Main Member Link ID],Table3[[#This Row],[Main Member Link ID]]),"Yes","")) | U3: =IF(Table3[[#This Row],[Member Type]]="Child", IF(AND(Table3[[#This Row],[Is Child Sum Cover Highest?]]="Yes",Table3[[#This Row],[Each Child Premium]]=_xlfn.MAXIFS($R$3:$R$98,$B$3:$B$98,"Child",$C$3:$C$98,Table3[[#This Row],[Main Member Link ID]]),Table3[[#This Row],[No. of Child with same Cover Amont under a policy]]=1),1, IF(AND(Table3[[#This Row],[Is Child Sum Cover Highest?]]="Yes",Table3[[#This Row],[Each Child Premium]]=_xlfn.MAXIFS($R$3:$R$98,$B$3:$B$98,"Child",$C$3:$C$98,Table3[[#This Row],[Main Member Link ID]]),Table3[[#This Row],[No. of Child with same Cover Amont under a policy]]>1,J3=_xlfn.MINIFS(Table3[Age],Table3[Member Type],"Child",Table3[Main Member Link ID],Table3[[#This Row],[Main Member Link ID]],Table3[No. of Child with same Cover Amont under a policy],Table3[[#This Row],[No. of Child with same Cover Amont under a policy]])),1,0)),0) -> 0
B4: =Members!B6 -> Spouse | C4: =Members!E6 -> 9403175256087 | D4: =Members!F6 -> 9403175091187 | E4: =Members!G6 -> 0 | F4: =Members!H6 -> 32339 | G4: =Members!I6 -> Male | H4: =Members!J6 -> Consolidated Funeral - Spouse | I4: =Members!K6 -> 46082 | J4: =IFERROR(DATEDIF(F4,I4,"Y")+1,0) -> 38 | K4: =IFERROR(IF(OR(B4=0,Table3[[#This Row],[Age]]=0,Table3[[#This Row],[Member Type]]="Beneficiary"),0, IF(B4="Main Member",VLOOKUP(J4,Rate_MM,5), IF(B4="Spouse",VLOOKUP(J4,Rate_SP,5), IF(B4="Extended",VLOOKUP(J4,Rate_EXT,5), IF(B4="Parent",VLOOKUP(J4,Rate_PAR,5), IF(B4="Child",VLOOKUP(J4,Rate_CH,5))))))),0) -> 13.8125 | L4: =IFERROR(IF(OR(B4=0,Table3[[#This Row],[Age]]=0,Table3[[#This Row],[Member Type]]="Beneficiary"),0, IF(B4="Main Member",VLOOKUP(J4,Rate_MM,4), IF(B4="Spouse",VLOOKUP(J4,Rate_SP,4), IF(B4="Extended",VLOOKUP(J4,Rate_EXT,4), IF(B4="Parent",VLOOKUP(J4,Rate_PAR,4), IF(B4="Child",VLOOKUP(J4,Rate_CH,4))))))),0) -> 0 | M4: =Members!N6 -> 100000 | N4: =IF(Table3[[#This Row],[Member Type]]<>"Child",Table3[[#This Row],[Rate per 10,000]]/10000*Table3[[#This Row],[Cover Amount]]+IF(Table3[[#This Row],[Cover Amount]]>0,Table3[[#This Row],[Fixed Rate]],0), IF(AND(Table3[[#This Row],[Member Type]]="Child",Table3[[#This Row],[Count of Member Type]]>6),0,Table3[[#This Row],[Each Child Premium]]*Table3[[#This Row],[Allocation of Child Premium]]+IF(Table3[[#This Row],[Cover Amount]]>0,Table3[[#This Row],[Fixed Rate]],0))) -> 138.125 | O4: =IF(Table3[[#This Row],[Member Type]]=0,0, IF(AND(Table3[[#This Row],[Member Type]]="Child",Table3[[#This Row],[Count of Member Type]]>6),-1, IF(AND(Table3[[#This Row],[Member Type]]="Extended",Table3[[#This Row],[Count of Member Type]]>10),-2, IF(AND(Table3[[#This Row],[Member Type]]="Parent",Table3[[#This Row],[Count of Member Type]]>4),-3, IF(AND(Table3[[#This Row],[Member Type]]="Beneficiary",Table3[[#This Row],[Count of Member Type]]>6),-4, IF(AND(Table3[[#This Row],[Member Type]]="Beneficiary",Table3[[#This Row],[Count of Member Type]]<=6),0, IF(OR(Table3[[#This Row],[Age]]>75,Table3[[#This Row],[Age]]="#NUM!"),-6, IFERROR( IF(AND(Table3[[#This Row],[Age]]<Child_OverAgeRange,Table3[[#This Row],[Member Type]]="Child"), MIN(VLOOKUP(Table3[[#This Row],[Age]],'Rates Lookup'!$H$9:$J$12,3,TRUE),VLOOKUP(Table3[[#This Row],[Age]],'Rates Lookup'!$H$9:$J$12,2,TRUE)*_xlfn.XLOOKUP(Table3[[#This Row],[Main Member Link ID]],Table3[Main Member Link ID],Table3[Cover Amount],0)), IF(AND(Table3[[#This Row],[Age]]>=Child_OverAgeRange,Table3[[#This Row],[Member Type]]="Child"),-5, IF(AND(Table3[[#This Row],[Age]]<Extended_OverAgeRange,Table3[[#This Row],[Member Type]]="Extended"), MIN(VLOOKUP(Table3[[#This Row],[Age]],'Rates Lookup'!$H$14:$J$17,3,TRUE),VLOOKUP(Table3[[#This Row],[Age]],'Rates Lookup'!$H$14:$J$17,2,TRUE)*_xlfn.XLOOKUP(Table3[[#This Row],[Main Member Link ID]],Table3[Main Member Link ID],Table3[Cover Amount],0)), IF(AND(Table3[[#This Row],[Age]]>=Extended_OverAgeRange,Table3[[#This Row],[Member Type]]="Extended"), MIN(VLOOKUP(Table3[[#This Row],[Age]],'Rates Lookup'!$H$14:$J$17,3,TRUE),VLOOKUP(Table3[[#This Row],[Age]],'Rates Lookup'!$H$14:$J$17,2,TRUE)*_xlfn.XLOOKUP(Table3[[#This Row],[Main Member Link ID]],Table3[Main Member Link ID],Table3[Cover Amount],0)), IF(Table3[[#This Row],[Member Type]]="Main Member",VLOOKUP(Table3[[#This Row],[Member Type]],'Rates Lookup'!$H$4:$J$17,3,FALSE), IF(OR(Table3[[#This Row],[Member Type]]="Spouse",Table3[[#This Row],[Member Type]]="Parent"),MIN(VLOOKUP(Table3[[#This Row],[Member Type]],'Rates Lookup'!$H$4:$J$17,3,FALSE),VLOOKUP(Table3[[#This Row],[Member Type]],'Rates Lookup'!$H$4:$J$17,2,FALSE)*_xlfn.XLOOKUP(Table3[[#This Row],[Main Member Link ID]],Table3[Main Member Link ID],Table3[Cover Amount],0)))))))),-6)))))))) -> 120000 | P4: =IF(Table3[[#This Row],[Member Type]]="Child",COUNTIFS($B$3:$B$98,"Child",$C$3:$C$98,Table3[[#This Row],[Main Member Link ID]])-COUNTIFS($B5:$B$98,"Child",$C5:$C$98,Table3[[#This Row],[Main Member Link ID]]), IF(Table3[[#This Row],[Member Type]]="Extended",COUNTIFS($B$3:$B$98,"Extended",$C$3:$C$98,Table3[[#This Row],[Main Member Link ID]])-COUNTIFS($B5:$B$98,"Extended",$C5:$C$98,Table3[[#This Row],[Main Member Link ID]]), IF(Table3[[#This Row],[Member Type]]="Parent",COUNTIFS($B$3:$B$98,"Parent",$C$3:$C$98,Table3[[#This Row],[Main Member Link ID]])-COUNTIFS($B5:$B$98,"Parent",$C5:$C$98,Table3[[#This Row],[Main Member Link ID]]), IF(Table3[[#This Row],[Member Type]]="Spouse",COUNTIFS($B$3:$B$98,"Spouse",$C$3:$C$98,Table3[[#This Row],[Main Member Link ID]])-COUNTIFS($B5:$B$98,"Spouse",$C5:$C$98,Table3[[#This Row],[Main Member Link ID]]), IF(Table3[[#This Row],[Member Type]]="Main Member",COUNTIFS($B$3:$B$98,"Main Member",$C$3:$C$98,Table3[[#This Row],[Main Member Link ID]])-COUNTIFS($B5:$B$98,"Main Member",$C5:$C$98,Table3[[#This Row],[Main Member Link ID]]), IF(Table3[[#This Row],[Member Type]]="Beneficiary",COUNTIFS($B$3:$B$98,"Beneficiary",$C$3:$C$98,Table3[[#This Row],[Main Member Link ID]])-COUNTIFS($B5:$B$98,"Beneficiary",$C5:$C$98,Table3[[#This Row],[Main Member Link ID]]),0)))))) -> 1 | Q4: =IF(Table3[[#This Row],[Indicative Max Sum Cover for each Member Type]]=-1,"Exceeded number of lives allowed for Child member type", IF(Table3[[#This Row],[Indicative Max Sum Cover for each Member Type]]=-2,"Exceeded number of lives allowed for Extended member type", IF(Table3[[#This Row],[Indicative Max Sum Cover for each Member Type]]=-3,"Exceeded number of lives allowed for Parent member type", IF(Table3[[#This Row],[Indicative Max Sum Cover for each Member Type]]=-4,"Exceeded number of lives allowed for Beneficiary member type", IF(Table3[[#This Row],[Indicative Max Sum Cover for each Member Type]]=-5,"Change to Extended member type", IF(Table3[[#This Row],[Indicative Max Sum Cover for each Member Type]]=-6,"Check Member Type or Date of Birth",Table3[[#This Row],[Indicative Max Sum Cover for each Member Type]])))))) -> 120000 | R4: =IF(Table3[[#This Row],[Member Type]]="Child",Table3[[#This Row],[Rate per 10,000]]/10000*Table3[[#This Row],[Cover Amount]],0) -> 0 | S4: =IF(Table3[[#This Row],[Member Type]]="Child",COUNTIFS(Table3[Each Child Premium],Table3[[#This Row],[Each Child Premium]],Table3[Main Member Link ID],Table3[[#This Row],[Main Member Link ID]]),0) -> 0 | T4: =IF(Table3[[#This Row],[No. of Child with same Cover Amont under a policy]]=0,"",IF(Table3[[#This Row],[Each Child Premium]]>=_xlfn.MAXIFS(Table3[Each Child Premium],Table3[Main Member Link ID],Table3[[#This Row],[Main Member Link ID]]),"Yes","")) | U4: =IF(Table3[[#This Row],[Member Type]]="Child", IF(AND(Table3[[#This Row],[Is Child Sum Cover Highest?]]="Yes",Table3[[#This Row],[Each Child Premium]]=_xlfn.MAXIFS($R$3:$R$98,$B$3:$B$98,"Child",$C$3:$C$98,Table3[[#This Row],[Main Member Link ID]]),Table3[[#This Row],[No. of Child with same Cover Amont under a policy]]=1),1, IF(AND(Table3[[#This Row],[Is Child Sum Cover Highest?]]="Yes",Table3[[#This Row],[Each Child Premium]]=_xlfn.MAXIFS($R$3:$R$98,$B$3:$B$98,"Child",$C$3:$C$98,Table3[[#This Row],[Main Member Link ID]]),Table3[[#This Row],[No. of Child with same Cover Amont under a policy]]>1,J4=_xlfn.MINIFS(Table3[Age],Table3[Member Type],"Child",Table3[Main Member Link ID],Table3[[#This Row],[Main Member Link ID]],Table3[No. of Child with same Cover Amont under a policy],Table3[[#This Row],[No. of Child with same Cover Amont under a policy]])),1,0)),0) -> 0
B5: =Members!B7 -> Beneficiary | C5: =Members!E7 -> 9706160746189 | D5: =Members!F7 -> 9403177609184 | E5: =Members!G7 -> 0 | F5: =Members!H7 -> 37714 | G5: =Members!I7 -> Male | H5: =Members!J7 | I5: =Members!K7 -> 46082 | J5: =IFERROR(DATEDIF(F5,I5,"Y")+1,0) -> 23 | K5: =IFERROR(IF(OR(B5=0,Table3[[#This Row],[Age]]=0,Table3[[#This Row],[Member Type]]="Beneficiary"),0, IF(B5="Main Member",VLOOKUP(J5,Rate_MM,5), IF(B5="Spouse",VLOOKUP(J5,Rate_SP,5), IF(B5="Extended",VLOOKUP(J5,Rate_EXT,5), IF(B5="Parent",VLOOKUP(J5,Rate_PAR,5), IF(B5="Child",VLOOKUP(J5,Rate_CH,5))))))),0) -> 0 | L5: =IFERROR(IF(OR(B5=0,Table3[[#This Row],[Age]]=0,Table3[[#This Row],[Member Type]]="Beneficiary"),0, IF(B5="Main Member",VLOOKUP(J5,Rate_MM,4), IF(B5="Spouse",VLOOKUP(J5,Rate_SP,4), IF(B5="Extended",VLOOKUP(J5,Rate_EXT,4), IF(B5="Parent",VLOOKUP(J5,Rate_PAR,4), IF(B5="Child",VLOOKUP(J5,Rate_CH,4))))))),0) -> 0 | M5: =Members!N7 -> 100000 | N5: =IF(Table3[[#This Row],[Member Type]]<>"Child",Table3[[#This Row],[Rate per 10,000]]/10000*Table3[[#This Row],[Cover Amount]]+IF(Table3[[#This Row],[Cover Amount]]>0,Table3[[#This Row],[Fixed Rate]],0), IF(AND(Table3[[#This Row],[Member Type]]="Child",Table3[[#This Row],[Count of Member Type]]>6),0,Table3[[#This Row],[Each Child Premium]]*Table3[[#This Row],[Allocation of Child Premium]]+IF(Table3[[#This Row],[Cover Amount]]>0,Table3[[#This Row],[Fixed Rate]],0))) -> 0 | O5: =IF(Table3[[#This Row],[Member Type]]=0,0, IF(AND(Table3[[#This Row],[Member Type]]="Child",Table3[[#This Row],[Count of Member Type]]>6),-1, IF(AND(Table3[[#This Row],[Member Type]]="Extended",Table3[[#This Row],[Count of Member Type]]>10),-2, IF(AND(Table3[[#This Row],[Member Type]]="Parent",Table3[[#This Row],[Count of Member Type]]>4),-3, IF(AND(Table3[[#This Row],[Member Type]]="Beneficiary",Table3[[#This Row],[Count of Member Type]]>6),-4, IF(AND(Table3[[#This Row],[Member Type]]="Beneficiary",Table3[[#This Row],[Count of Member Type]]<=6),0, IF(OR(Table3[[#This Row],[Age]]>75,Table3[[#This Row],[Age]]="#NUM!"),-6, IFERROR( IF(AND(Table3[[#This Row],[Age]]<Child_OverAgeRange,Table3[[#This Row],[Member Type]]="Child"), MIN(VLOOKUP(Table3[[#This Row],[Age]],'Rates Lookup'!$H$9:$J$12,3,TRUE),VLOOKUP(Table3[[#This Row],[Age]],'Rates Lookup'!$H$9:$J$12,2,TRUE)*_xlfn.XLOOKUP(Table3[[#This Row],[Main Member Link ID]],Table3[Main Member Link ID],Table3[Cover Amount],0)), IF(AND(Table3[[#This Row],[Age]]>=Child_OverAgeRange,Table3[[#This Row],[Member Type]]="Child"),-5, IF(AND(Table3[[#This Row],[Age]]<Extended_OverAgeRange,Table3[[#This Row],[Member Type]]="Extended"), MIN(VLOOKUP(Table3[[#This Row],[Age]],'Rates Lookup'!$H$14:$J$17,3,TRUE),VLOOKUP(Table3[[#This Row],[Age]],'Rates Lookup'!$H$14:$J$17,2,TRUE)*_xlfn.XLOOKUP(Table3[[#This Row],[Main Member Link ID]],Table3[Main Member Link ID],Table3[Cover Amount],0)), IF(AND(Table3[[#This Row],[Age]]>=Extended_OverAgeRange,Table3[[#This Row],[Member Type]]="Extended"), MIN(VLOOKUP(Table3[[#This Row],[Age]],'Rates Lookup'!$H$14:$J$17,3,TRUE),VLOOKUP(Table3[[#This Row],[Age]],'Rates Lookup'!$H$14:$J$17,2,TRUE)*_xlfn.XLOOKUP(Table3[[#This Row],[Main Member Link ID]],Table3[Main Member Link ID],Table3[Cover Amount],0)), IF(Table3[[#This Row],[Member Type]]="Main Member",VLOOKUP(Table3[[#This Row],[Member Type]],'Rates Lookup'!$H$4:$J$17,3,FALSE), IF(OR(Table3[[#This Row],[Member Type]]="Spouse",Table3[[#This Row],[Member Type]]="Parent"),MIN(VLOOKUP(Table3[[#This Row],[Member Type]],'Rates Lookup'!$H$4:$J$17,3,FALSE),VLOOKUP(Table3[[#This Row],[Member Type]],'Rates Lookup'!$H$4:$J$17,2,FALSE)*_xlfn.XLOOKUP(Table3[[#This Row],[Main Member Link ID]],Table3[Main Member Link ID],Table3[Cover Amount],0)))))))),-6)))))))) -> 0 | P5: =IF(Table3[[#This Row],[Member Type]]="Child",COUNTIFS($B$3:$B$98,"Child",$C$3:$C$98,Table3[[#This Row],[Main Member Link ID]])-COUNTIFS($B6:$B$98,"Child",$C6:$C$98,Table3[[#This Row],[Main Member Link ID]]), IF(Table3[[#This Row],[Member Type]]="Extended",COUNTIFS($B$3:$B$98,"Extended",$C$3:$C$98,Table3[[#This Row],[Main Member Link ID]])-COUNTIFS($B6:$B$98,"Extended",$C6:$C$98,Table3[[#This Row],[Main Member Link ID]]), IF(Table3[[#This Row],[Member Type]]="Parent",COUNTIFS($B$3:$B$98,"Parent",$C$3:$C$98,Table3[[#This Row],[Main Member Link ID]])-COUNTIFS($B6:$B$98,"Parent",$C6:$C$98,Table3[[#This Row],[Main Member Link ID]]), IF(Table3[[#This Row],[Member Type]]="Spouse",COUNTIFS($B$3:$B$98,"Spouse",$C$3:$C$98,Table3[[#This Row],[Main Member Link ID]])-COUNTIFS($B6:$B$98,"Spouse",$C6:$C$98,Table3[[#This Row],[Main Member Link ID]]), IF(Table3[[#This Row],[Member Type]]="Main Member",COUNTIFS($B$3:$B$98,"Main Member",$C$3:$C$98,Table3[[#This Row],[Main Member Link ID]])-COUNTIFS($B6:$B$98,"Main Member",$C6:$C$98,Table3[[#This Row],[Main Member Link ID]]), IF(Table3[[#This Row],[Member Type]]="Beneficiary",COUNTIFS($B$3:$B$98,"Beneficiary",$C$3:$C$98,Table3[[#This Row],[Main Member Link ID]])-COUNTIFS($B6:$B$98,"Beneficiary",$C6:$C$98,Table3[[#This Row],[Main Member Link ID]]),0)))))) -> 1 | Q5: =IF(Table3[[#This Row],[Indicative Max Sum Cover for each Member Type]]=-1,"Exceeded number of lives allowed for Child member type", IF(Table3[[#This Row],[Indicative Max Sum Cover for each Member Type]]=-2,"Exceeded number of lives allowed for Extended member type", IF(Table3[[#This Row],[Indicative Max Sum Cover for each Member Type]]=-3,"Exceeded number of lives allowed for Parent member type", IF(Table3[[#This Row],[Indicative Max Sum Cover for each Member Type]]=-4,"Exceeded number of lives allowed for Beneficiary member type", IF(Table3[[#This Row],[Indicative Max Sum Cover for each Member Type]]=-5,"Change to Extended member type", IF(Table3[[#This Row],[Indicative Max Sum Cover for each Member Type]]=-6,"Check Member Type or Date of Birth",Table3[[#This Row],[Indicative Max Sum Cover for each Member Type]])))))) -> 0 | R5: =IF(Table3[[#This Row],[Member Type]]="Child",Table3[[#This Row],[Rate per 10,000]]/10000*Table3[[#This Row],[Cover Amount]],0) -> 0 | S5: =IF(Table3[[#This Row],[Member Type]]="Child",COUNTIFS(Table3[Each Child Premium],Table3[[#This Row],[Each Child Premium]],Table3[Main Member Link ID],Table3[[#This Row],[Main Member Link ID]]),0) -> 0 | T5: =IF(Table3[[#This Row],[No. of Child with same Cover Amont under a policy]]=0,"",IF(Table3[[#This Row],[Each Child Premium]]>=_xlfn.MAXIFS(Table3[Each Child Premium],Table3[Main Member Link ID],Table3[[#This Row],[Main Member Link ID]]),"Yes","")) | U5: =IF(Table3[[#This Row],[Member Type]]="Child", IF(AND(Table3[[#This Row],[Is Child Sum Cover Highest?]]="Yes",Table3[[#This Row],[Each Child Premium]]=_xlfn.MAXIFS($R$3:$R$98,$B$3:$B$98,"Child",$C$3:$C$98,Table3[[#This Row],[Main Member Link ID]]),Table3[[#This Row],[No. of Child with same Cover Amont under a policy]]=1),1, IF(AND(Table3[[#This Row],[Is Child Sum Cover Highest?]]="Yes",Table3[[#This Row],[Each Child Premium]]=_xlfn.MAXIFS($R$3:$R$98,$B$3:$B$98,"Child",$C$3:$C$98,Table3[[#This Row],[Main Member Link ID]]),Table3[[#This Row],[No. of Child with same Cover Amont under a policy]]>1,J5=_xlfn.MINIFS(Table3[Age],Table3[Member Type],"Child",Table3[Main Member Link ID],Table3[[#This Row],[Main Member Link ID]],Table3[No. of Child with same Cover Amont under a policy],Table3[[#This Row],[No. of Child with same Cover Amont under a policy]])),1,0)),0) -> 0
