Workbook
Name Ext: 'Funeral premiums'!$E$41:$G$52
Name MM: 'Funeral premiums'!$E$3:$S$13
Name MM_CH: 'Funeral premiums'!$E$14:$S$22
Name MM_LIFE: 'Life premiums'!$E$6:$S$14
Name MM_SP: 'Funeral premiums'!$E$23:$S$31
Name MM_SP_CH: 'Funeral premiums'!$E$32:$S$40
Name Par: 'Funeral premiums'!$E$53:$G$63
Name SP_LIFE: 'Life premiums'!$E$15:$S$23

Sheet Important Notes
D2: #VALUE!
D3: Quick Guide to completing the My Value Plus Onboarding Sheet
D4: 1. Kindly ensure that you do not skip a row. 2. Always start with the Main Member followed by --> Spouse --> Child --> Parent --> Extended --> Beneficiary. 3. Indicate the client type (Member Type) by choosing from the list in column (B). 4. Maximum number of lives per Member Type: a) Main Member - 1 life b) Spouse - 1 life c) Child - 6 lives (from the 7th child onwards please add them as part of the Extended member type) d) Parent - 4 lives e) Extended - 10 lives f) Beneficiaries - 6 lives 5. Always indicate the Main Member Link ID (ID or Passport Number) in column (E) for all Member Type linked to the Main Member. 6. Always add a member ID Number in column (F) or Passport Number in column (G). 7. Always capture a Date of Birth in column (H) and a Commencement Date in column (J). This will determine the correct Age Next Birthday for premium calculations. 8. Product Details are captured from the selections made from the list provided in each cells of columns (K-O). 9. Insert the required Cover Amount in columns (Q-R) taking note of the specific limitations shown in the cells of these columns. 10. Column (BF) populates the allowable Funeral Cover Amount based on the Member Type that is linked to the Main Member. Please refer to this column when deciding on the funeral sum cover amount. 11. Always add a Beneficiary for every Main Member and input the benefit % split for every beneficiary in columns (V-W). 12. The Funeral Cover Amount and the Accidental Death Income Benefit will only be paid to one Beneficiary (with no split %) i.e. insert 100% in column (W). 13. The Life cover can have any number of beneficiaries, please ensure each split % in column (V) sums up to 100% for every policy of a Main Member. 14. Indicate a Preferred Method of Communication by choosing from the list in column (AS). 15. Spouse and Children's details must be captured individually although the funeral benefit premium is calculated under the Main Member's selected benefit option. 16. Parent and Extended premiums are independent of the Main Member's age or cover amount. 17. Premiums are auto-populated in column (S) for Life, in column (T) for Funeral and column (U) sums the two premiums as the Total Premium excluding the VAPs amount.
D6: Quick Guide to the Product Details
D7: 1. The My Value Plus Life is available to the Main Member and Spouse. 2. The My Value Plus Life and Funeral is available to the Main Member and Spouse (for both Life and Funeral cover) and to the Child, Parent and Extended (for Funeral cover only). 3. Life cover starts from a minimum of R50,000 and up to a maximum of R500,000 per life. The cover for Spouse cannot exceed the Main Member's Life cover amount. 4. Funeral cover starts from a minimum of R10,000 (for all Member Type) and should not exceed the Main Member's Funeral cover amount, up to a maximum of: a) R150,000 per life (for Main Member and Spouse); b) R75,000 per life (for Parent and Extended where Age Next Birthday is greater than 21 years old); c) 100% of Main Member's funeral cover amount up to a max of R50,000 per life (for Child and Extended where Age Next Birthday between 15 and 21 years old); d) 50% of Main Member's funeral cover amount up to a max of R50,000 per life (for Child and Extended where Age Next Birthday between 7 and 14 years old); e) 25% of Main Member's funeral cover amount up to a max of R20,000 per life (for Child and Extended where Age Next Birthday between 1 and 6 years); f) 12.5% of Main Member's funeral cover amount up to a max of R12,500 (for Stillborn Child - this is an automatic feature on the Main Member's cover). 5. There is no underwriting for this product. 6. Age is derived as Age Next Birthday calculated based on the Commencement Date and Date of Birth of the member. 7. Premiums for Life cover is calculated based on the age of the Main Member and Spouse, respectively. Premiums for Funeral cover is calculated based on the age of the Main Member and differs based on the benefit option chosen (i.e. where a Spouse and/or Child is included for funeral cover). Funeral cover premiums for Parent and Extended members are calculated separately based on the age of the individual member. 8. Premium Waiver options (see list provided in the Onboarding sheet) are available to the Main Member under this product with an additional premium payable for this benefit. The Death premium waiver waives the premiums for Spouse and Child for a selected term upon death of the Main Member whilst the Retirement waiver waives the premiums for Spouse and Child for a selected term upon the Main Member reaching the retirement age. The selected term can be either 5 or 10 years and is subject to a waiting period. Waiver benefit can only be taken out if the Main Member is younger than 56 at age next birthday. For replacement business the maximum entry age for the death waiver is 75 at Age Next Birthday. 9. VAPs are the value-added services (i.e. body repatriation, grocery, airtime, wills and tax benefits) that are compulsory (with further options) for this product at an additional fee. This is included in the Total Premium amount of the Main Member. Any chosen option to have a Premium Waiver benefit under this product will not waive the fee for the value-added services. 10. Income Benefit upon Accidental Death of the Main Member and Premium Cashback are embedded benefits of this product at no additional premium. a) The Accidental Death Income benefit is set at R1,000 monthly for 12 months. b) Premium Cashback is every January following the 1st policy anniversary. 11. Annual increase is optional. A selection of 5% or 7% is offered under this product. The selected annual increment % is applied annually on the premium and cover amount of all members under a policy and ceases when the Main Member reaches age next birthday of 66 years old.

Sheet Onboarding
A1: MVP_v1 | B1: #VALUE!
A2: MEMBERS | K2: Product Details | V2: Beneficiary Details | X2: Affordability | Y2: PREVIOUS INSURANCE | AD2: PHYSICAL ADDRESS | AJ2: POSTAL ADDRESS | AP2: COMMUNICATION | AT2: EMPLOYEE DETAILS | AX2: BANKING DETAILS | BD2: Sales Allocation
A3: To be completed for existing policies only | B3: (select Role from list) | C3: (key in Member's Name) | E3: (key in Main Member's ID / Passport No. for all selected Roles) | F3: (key in Member's Identification No.) | H3: (key in DOB in this format yyyy-mm-dd) | I3: (select Gender from list) | J3: (key in Cover Start Date in this format yyyy-mm-dd) | K3: (select Product from list) | L3: (select type of benefit from list) | M3: (select type of Premium Waiver from list) | N3: (select category of VAPs from list) | O3: (select from list) | P3: (auto populated -DO NOT EDIT-) | Q3: (key in life cover amount) | R3: (key in funeral cover amount) | S3: (premium is populated automatically) -DO NOT EDIT- | V3: (key in the expected distributed portion of the cover amount to the beneficiaries upon death of the main member) | X3: (Can the client afford the quoted premium amount?) | Y3: (select company name from list) | Z3: (key in details) | AA3: (key in date in this format yyyy-mm-dd) | AC3: (key in details) | AD3: (key in Str No. & Name) | AE3: (key in Suburb) | AF3: (key in details) | AG3: (key in details) | AH3: (key in details) | AI3: (key in Area Code) | AJ3: (key in P.O. Box or Private Bag) | AK3: (key in Suburb) | AL3: (key in details) | AM3: (key in details) | AN3: (key in details) | AO3: (key in Postal Code) | AP3: (key in details) | AQ3: (key in details) | AR3: (key in details) | AS3: (select comm method from list) | AT3: (key in details) | AU3: (key in details) | AV3: (key in details) | AW3: (key in details) | AX3: (select from list) | AY3: (key in details) | AZ3: (key in details) | BA3: (key in details) | BB3: (key in details) | BC3: (key in details) | BD3: (key in details)
A4: Policy Number | B4: Member Type | C4: First Name | D4: Surname | E4: Main Member Link ID | F4: ID Number | G4: Passport Number | H4: Date Of Birth | I4: Gender | J4: Commencement Date | K4: Product Option | L4: Benefit Option | M4: Premium Waiver | N4: VAPs Options | O4: Annual Increase Option | P4: Increase Month | Q4: Life Cover Amount | R4: Funeral Cover Amount | S4: Life Premium | T4: Funeral Premium | U4: Total Premium (inc. Funeral premium under Main Member and excl. VAPs) | V4: Life Benefit Percentage Split | W4: Funeral Benefit & Accidental Death Income Benefit Percentage Split | X4: Affordability Status | Y4: Previous Insurer | Z4: Previous Insurer Policy Number | AA4: Previous Insurer Join Date | AB4: Previous Insurer Cancellation Date | AC4: Previous Cover Amount | AD4: Address 1 | AE4: Address 2 | AF4: City | AG4: Province | AH4: Country | AI4: Area Code | AJ4: Postal Address 1 | AK4: Postal Address 2 | AL4: Postal City | AM4: Postal Province | AN4: Postal Country | AO4: Postal Code | AP4: Telephone | AQ4: Mobile | AR4: Email | AS4: Preferred Method Of Communication | AT4: Payroll Code | AU4: Employer | AV4: Employee Number | AW4: Department | AX4: Payment Method | AY4: Bank | AZ4: Branch Code | BA4: Account# | BB4: Account Type | BC4: Debit Order Day | BD4: Representative ID | BF4: Applicable Funeral Cover Amount
B5: Main Member | C5: JOHN | D5: Doe | E5: 9403175795084 | F5: 9403175795084 | H5: 34410 | I5: Female | J5: 46023 | K5: My Value Plus Life | L5: Life - Main Member | M5: Death only - 5 years | N5: Compulsory and Optional (R 9.13) | O5: 0.05 | P5: =IF(OR(Table13[[#This Row],[Annual Increase Option]]="No increase",Table13[[#This Row],[Annual Increase Option]]=""),"",_xlfn.XLOOKUP(MONTH(Table13[[#This Row],[Commencement Date]]),Lookups!$I$19:$I$30,Lookups!$J$19:$J$30,0)) -> January | Q5: 100000 | R5: 50000 | S5: =IF(Table13[[#This Row],[Life Cover Amount]]="",0,Table2[[#This Row],[Life Premium]]) -> 249.75 | T5: =IF(Table13[[#This Row],[Funeral Cover Amount]]=0,0,Table2[[#This Row],[Funeral Premium]]) -> 0 | U5: =IF(AND(Table13[[#This Row],[Life Cover Amount]]="",Table13[[#This Row],[Funeral Cover Amount]]=""),0,onboarding_calcs!AA5) -> 249.75 | X5: Affordable | Y5: Hollard Life | Z5: 895-58584 | AA5: 43831 | AB5: 45658 | AC5: 500 | AD5: new | AE5: address | AF5: city | AG5: province | AH5: country | AI5: 1901 | AJ5: 99 | AK5: postal | AL5: pcity | AM5: pprovince | AN5: pcountry | AO5: pcode | AP5: 115970440 | AQ5: 0678978998 | AR5: abalusu@randmutual.co.za | AS5: Email | AT5: 94 | AU5: RMA | AV5: 19072082 | AW5: IT | AX5: Government Salary Deduction | AY5: CAPITEC | AZ5: 470010 | BA5: 1455098026 | BB5: SAVINGS | BC5: 1 | BD5: 8801215275085 | BF5: =IF(Table2[[#This Row],[Upper bound for age]]=FALSE,"Check Date of Birth or Commencement Date", IF(Table2[[#This Row],[Upper bound for age]]="Max age","Check Max Entry Age", IF(AND(Table13[[#This Row],[Member Type]]="Child",Table2[[#This Row],[Age Next Birthday]]>21),"Change Member Type to Extended", IFERROR(IF(OR(Table13[[#This Row],[Product Option]]="My Value Plus Life",Table13[[#This Row],[Member Type]]="Beneficiary"),"Not applicable", IF(AND(Table13[[#This Row],[Member Type]],Table13[[#This Row],[Product Option]]="My Value Plus Life & Funeral")="Main Member","Any amount from R10,000 to R150,000", IF(AND(OR(Table13[[#This Row],[Member Type]]="Spouse",Table13[[#This Row],[Member Type]]="Child"),Table13[[#This Row],[Product Option]]="My Value Plus Life & Funeral"),Table2[[#This Row],[Validation check for Funeral Cover Amount]], IF(AND(OR(Table13[[#This Row],[Member Type]]="Extended",Table13[[#This Row],[Member Type]]="Parent"),Table13[[#This Row],[Product Option]]="My Value Plus Life & Funeral"),"Any amount from R10,000 to "&TEXT(Table2[[#This Row],[Validation check for Funeral Cover Amount]],"R#,##0"), IF(Table13[[#This Row],[Member Type]]="","", ))))),"Check Date of Birth or Commencement Date")))) -> Not applicable
B6: Spouse | C6: DOE | D6: WIFES | E6: 9403175795084 | F6: 9404172666088 | H6: 34410 | I6: Male | J6: 46023 | K6: My Value Plus Life | L6: Life - Spouse | P6: =IF(OR(Table13[[#This Row],[Annual Increase Option]]="No increase",Table13[[#This Row],[Annual Increase Option]]=""),"",_xlfn.XLOOKUP(MONTH(Table13[[#This Row],[Commencement Date]]),Lookups!$I$19:$I$30,Lookups!$J$19:$J$30,0)) | Q6: 100000 | R6: 100 | S6: =IF(Table13[[#This Row],[Life Cover Amount]]="",0,Table2[[#This Row],[Life Premium]]) -> 153.05268 | T6: =IF(Table13[[#This Row],[Funeral Cover Amount]]=0,0,Table2[[#This Row],[Funeral Premium]]) -> 0 | U6: =IF(AND(Table13[[#This Row],[Life Cover Amount]]="",Table13[[#This Row],[Funeral Cover Amount]]=""),0,onboarding_calcs!AA6) -> 153.05268 | BF6: =IF(Table2[[#This Row],[Upper bound for age]]=FALSE,"Check Date of Birth or Commencement Date", IF(Table2[[#This Row],[Upper bound for age]]="Max age","Check Max Entry Age", IF(AND(Table13[[#This Row],[Member Type]]="Child",Table2[[#This Row],[Age Next Birthday]]>21),"Change Member Type to Extended", IFERROR(IF(OR(Table13[[#This Row],[Product Option]]="My Value Plus Life",Table13[[#This Row],[Member Type]]="Beneficiary"),"Not applicable", IF(AND(Table13[[#This Row],[Member Type]],Table13[[#This Row],[Product Option]]="My Value Plus Life & Funeral")="Main Member","Any amount from R10,000 to R150,000", IF(AND(OR(Table13[[#This Row],[Member Type]]="Spouse",Table13[[#This Row],[Member Type]]="Child"),Table13[[#This Row],[Product Option]]="My Value Plus Life & Funeral"),Table2[[#This Row],[Validation check for Funeral Cover Amount]], IF(AND(OR(Table13[[#This Row],[Member Type]]="Extended",Table13[[#This Row],[Member Type]]="Parent"),Table13[[#This Row],[Product Option]]="My Value Plus Life & Funeral"),"Any amount from R10,000 to "&TEXT(Table2[[#This Row],[Validation check for Funeral Cover Amount]],"R#,##0"), IF(Table13[[#This Row],[Member Type]]="","", ))))),"Check Date of Birth or Commencement Date")))) -> Not applicable
B7: Parent | C7: Bundle | D7: NEL | E7: 9403175795084 | F7: 9404179085183 | G7: 1984-03-07 | H7: 34410 | I7: Male | J7: 46023 | K7: My Value Plus Life | P7: =IF(OR(Table13[[#This Row],[Annual Increase Option]]="No increase",Table13[[#This Row],[Annual Increase Option]]=""),"",_xlfn.XLOOKUP(MONTH(Table13[[#This Row],[Commencement Date]]),Lookups!$I$19:$I$30,Lookups!$J$19:$J$30,0)) | R7: 50000 | S7: =IF(Table13[[#This Row],[Life Cover Amount]]="",0,Table2[[#This Row],[Life Premium]]) -> 0 | T7: =IF(Table13[[#This Row],[Funeral Cover Amount]]=0,0,Table2[[#This Row],[Funeral Premium]]) -> 0 | U7: =IF(AND(Table13[[#This Row],[Life Cover Amount]]="",Table13[[#This Row],[Funeral Cover Amount]]=""),0,onboarding_calcs!AA7) -> 0 | BF7: =IF(Table2[[#This Row],[Upper bound for age]]=FALSE,"Check Date of Birth or Commencement Date", IF(Table2[[#This Row],[Upper bound for age]]="Max age","Check Max Entry Age", IF(AND(Table13[[#This Row],[Member Type]]="Child",Table2[[#This Row],[Age Next Birthday]]>21),"Change Member Type to Extended", IFERROR(IF(OR(Table13[[#This Row],[Product Option]]="My Value Plus Life",Table13[[#This Row],[Member Type]]="Beneficiary"),"Not applicable", IF(AND(Table13[[#This Row],[Member Type]],Table13[[#This Row],[Product Option]]="My Value Plus Life & Funeral")="Main Member","Any amount from R10,000 to R150,000", IF(AND(OR(Table13[[#This Row],[Member Type]]="Spouse",Table13[[#This Row],[Member Type]]="Child"),Table13[[#This Row],[Product Option]]="My Value Plus Life & Funeral"),Table2[[#This Row],[Validation check for Funeral Cover Amount]], IF(AND(OR(Table13[[#This Row],[Member Type]]="Extended",Table13[[#This Row],[Member Type]]="Parent"),Table13[[#This Row],[Product Option]]="My Value Plus Life & Funeral"),"Any amount from R10,000 to "&TEXT(Table2[[#This Row],[Validation check for Funeral Cover Amount]],"R#,##0"), IF(Table13[[#This Row],[Member Type]]="","", ))))),"Check Date of Birth or Commencement Date")))) -> Not applicable
B8: Beneficiary | C8: Oledy | D8: NEL | E8: 9403175795084 | F8: 9403175116182 | G8: 1966-01-01 | H8: 34410 | I8: Male | J8: 46023 | K8: My Value Plus Life | P8: =IF(OR(Table13[[#This Row],[Annual Increase Option]]="No increase",Table13[[#This Row],[Annual Increase Option]]=""),"",_xlfn.XLOOKUP(MONTH(Table13[[#This Row],[Commencement Date]]),Lookups!$I$19:$I$30,Lookups!$J$19:$J$30,0)) | S8: =IF(Table13[[#This Row],[Life Cover Amount]]="",0,Table2[[#This Row],[Life Premium]]) -> 0 | T8: =IF(Table13[[#This Row],[Funeral Cover Amount]]=0,0,Table2[[#This Row],[Funeral Premium]]) -> 0 | U8: =IF(AND(Table13[[#This Row],[Life Cover Amount]]="",Table13[[#This Row],[Funeral Cover Amount]]=""),0,onboarding_calcs!AA8) -> 0 | V8: 0.3 | BF8: =IF(Table2[[#This Row],[Upper bound for age]]=FALSE,"Check Date of Birth or Commencement Date", IF(Table2[[#This Row],[Upper bound for age]]="Max age","Check Max Entry Age", IF(AND(Table13[[#This Row],[Member Type]]="Child",Table2[[#This Row],[Age Next Birthday]]>21),"Change Member Type to Extended", IFERROR(IF(OR(Table13[[#This Row],[Product Option]]="My Value Plus Life",Table13[[#This Row],[Member Type]]="Beneficiary"),"Not applicable", IF(AND(Table13[[#This Row],[Member Type]],Table13[[#This Row],[Product Option]]="My Value Plus Life & Funeral")="Main Member","Any amount from R10,000 to R150,000", IF(AND(OR(Table13[[#This Row],[Member Type]]="Spouse",Table13[[#This Row],[Member Type]]="Child"),Table13[[#This Row],[Product Option]]="My Value Plus Life & Funeral"),Table2[[#This Row],[Validation check for Funeral Cover Amount]], IF(AND(OR(Table13[[#This Row],[Member Type]]="Extended",Table13[[#This Row],[Member Type]]="Parent"),Table13[[#This Row],[Product Option]]="My Value Plus Life & Funeral"),"Any amount from R10,000 to "&TEXT(Table2[[#This Row],[Validation check for Funeral Cover Amount]],"R#,##0"), IF(Table13[[#This Row],[Member Type]]="","", ))))),"Check Date of Birth or Commencement Date")))) -> Not applicable
B9: Extended | C9: Nepal | D9: NEL | E9: 9403175795084 | F9: 9403178781081 | G9: 1973-01-01 | H9: 34410 | I9: Female | J9: 46023 | K9: My Value Plus Life | L9: Funeral - Extended | P9: =IF(OR(Table13[[#This Row],[Annual Increase Option]]="No increase",Table13[[#This Row],[Annual Increase Option]]=""),"",_xlfn.XLOOKUP(MONTH(Table13[[#This Row],[Commencement Date]]),Lookups!$I$19:$I$30,Lookups!$J$19:$J$30,0)) | R9: 50000 | S9: =IF(Table13[[#This Row],[Life Cover Amount]]="",0,Table2[[#This Row],[Life Premium]]) -> 0 | T9: =IF(Table13[[#This Row],[Funeral Cover Amount]]=0,0,Table2[[#This Row],[Funeral Premium]]) -> 160.463 | U9: =IF(AND(Table13[[#This Row],[Life Cover Amount]]="",Table13[[#This Row],[Funeral Cover Amount]]=""),0,onboarding_calcs!AA9) -> 160.463 | BF9: =IF(Table2[[#This Row],[Upper bound for age]]=FALSE,"Check Date of Birth or Commencement Date", IF(Table2[[#This Row],[Upper bound for age]]="Max age","Check Max Entry Age", IF(AND(Table13[[#This Row],[Member Type]]="Child",Table2[[#This Row],[Age Next Birthday]]>21),"Change Member Type to Extended", IFERROR(IF(OR(Table13[[#This Row],[Product Option]]="My Value Plus Life",Table13[[#This Row],[Member Type]]="Beneficiary"),"Not applicable", IF(AND(Table13[[#This Row],[Member Type]],Table13[[#This Row],[Product Option]]="My Value Plus Life & Funeral")="Main Member","Any amount from R10,000 to R150,000", IF(AND(OR(Table13[[#This Row],[Member Type]]="Spouse",Table13[[#This Row],[Member Type]]="Child"),Table13[[#This Row],[Product Option]]="My Value Plus Life & Funeral"),Table2[[#This Row],[Validation check for Funeral Cover Amount]], IF(AND(OR(Table13[[#This Row],[Member Type]]="Extended",Table13[[#This Row],[Member Type]]="Parent"),Table13[[#This Row],[Product Option]]="My Value Plus Life & Funeral"),"Any amount from R10,000 to "&TEXT(Table2[[#This Row],[Validation check for Funeral Cover Amount]],"R#,##0"), IF(Table13[[#This Row],[Member Type]]="","", ))))),"Check Date of Birth or Commencement Date")))) -> Not applicable
B10: Beneficiary | C10: Bobrus | D10: NEL | E10: 9403175795084 | F10: 9403179351181 | H10: 34410 | I10: Female | J10: 46023 | K10: My Value Plus Life | P10: =IF(OR(Table13[[#This Row],[Annual Increase Option]]="No increase",Table13[[#This Row],[Annual Increase Option]]=""),"",_xlfn.XLOOKUP(MONTH(Table13[[#This Row],[Commencement Date]]),Lookups!$I$19:$I$30,Lookups!$J$19:$J$30,0)) | S10: =IF(Table13[[#This Row],[Life Cover Amount]]="",0,Table2[[#This Row],[Life Premium]]) -> 0 | T10: =IF(Table13[[#This Row],[Funeral Cover Amount]]=0,0,Table2[[#This Row],[Funeral Premium]]) -> 0 | U10: =IF(AND(Table13[[#This Row],[Life Cover Amount]]="",Table13[[#This Row],[Funeral Cover Amount]]=""),0,onboarding_calcs!AA10) -> 0 | V10: 0.3 | W10: 1 | BF10: =IF(Table2[[#This Row],[Upper bound for age]]=FALSE,"Check Date of Birth or Commencement Date", IF(Table2[[#This Row],[Upper bound for age]]="Max age","Check Max Entry Age", IF(AND(Table13[[#This Row],[Member Type]]="Child",Table2[[#This Row],[Age Next Birthday]]>21),"Change Member Type to Extended", IFERROR(IF(OR(Table13[[#This Row],[Product Option]]="My Value Plus Life",Table13[[#This Row],[Member Type]]="Beneficiary"),"Not applicable", IF(AND(Table13[[#This Row],[Member Type]],Table13[[#This Row],[Product Option]]="My Value Plus Life & Funeral")="Main Member","Any amount from R10,000 to R150,000", IF(AND(OR(Table13[[#This Row],[Member Type]]="Spouse",Table13[[#This Row],[Member Type]]="Child"),Table13[[#This Row],[Product Option]]="My Value Plus Life & Funeral"),Table2[[#This Row],[Validation check for Funeral Cover Amount]], IF(AND(OR(Table13[[#This Row],[Member Type]]="Extended",Table13[[#This Row],[Member Type]]="Parent"),Table13[[#This Row],[Product Option]]="My Value Plus Life & Funeral"),"Any amount from R10,000 to "&TEXT(Table2[[#This Row],[Validation check for Funeral Cover Amount]],"R#,##0"), IF(Table13[[#This Row],[Member Type]]="","", ))))),"Check Date of Birth or Commencement Date")))) -> Not applicable
B11: Beneficiary | C11: Ben | D11: two | E11: 9403175795084 | F11: 9403175705083 | H11: 34410 | I11: Female | J11: 46023 | K11: My Value Plus Life | P11: =IF(OR(Table13[[#This Row],[Annual Increase Option]]="No increase",Table13[[#This Row],[Annual Increase Option]]=""),"",_xlfn.XLOOKUP(MONTH(Table13[[#This Row],[Commencement Date]]),Lookups!$I$19:$I$30,Lookups!$J$19:$J$30,0)) | S11: =IF(Table13[[#This Row],[Life Cover Amount]]="",0,Table2[[#This Row],[Life Premium]]) -> 0 | T11: =IF(Table13[[#This Row],[Funeral Cover Amount]]=0,0,Table2[[#This Row],[Funeral Premium]]) -> 0 | U11: =IF(AND(Table13[[#This Row],[Life Cover Amount]]="",Table13[[#This Row],[Funeral Cover Amount]]=""),0,onboarding_calcs!AA11) -> 0 | V11: 0.4 | BF11: =IF(Table2[[#This Row],[Upper bound for age]]=FALSE,"Check Date of Birth or Commencement Date", IF(Table2[[#This Row],[Upper bound for age]]="Max age","Check Max Entry Age", IF(AND(Table13[[#This Row],[Member Type]]="Child",Table2[[#This Row],[Age Next Birthday]]>21),"Change Member Type to Extended", IFERROR(IF(OR(Table13[[#This Row],[Product Option]]="My Value Plus Life",Table13[[#This Row],[Member Type]]="Beneficiary"),"Not applicable", IF(AND(Table13[[#This Row],[Member Type]],Table13[[#This Row],[Product Option]]="My Value Plus Life & Funeral")="Main Member","Any amount from R10,000 to R150,000", IF(AND(OR(Table13[[#This Row],[Member Type]]="Spouse",Table13[[#This Row],[Member Type]]="Child"),Table13[[#This Row],[Product Option]]="My Value Plus Life & Funeral"),Table2[[#This Row],[Validation check for Funeral Cover Amount]], IF(AND(OR(Table13[[#This Row],[Member Type]]="Extended",Table13[[#This Row],[Member Type]]="Parent"),Table13[[#This Row],[Product Option]]="My Value Plus Life & Funeral"),"Any amount from R10,000 to "&TEXT(Table2[[#This Row],[Validation check for Funeral Cover Amount]],"R#,##0"), IF(Table13[[#This Row],[Member Type]]="","", ))))),"Check Date of Birth or Commencement Date")))) -> Not applicable
B12: Parent | C12: New | D12: Amend | E12: 9403175795084 | F12: 9403178301187 | G12: 1991-01-01 | H12: 34410 | I12: Female | J12: 46023 | K12: My Value Plus Life | L12: Funeral - Parent | P12: =IF(OR(Table13[[#This Row],[Annual Increase Option]]="No increase",Table13[[#This Row],[Annual Increase Option]]=""),"",_xlfn.XLOOKUP(MONTH(Table13[[#This Row],[Commencement Date]]),Lookups!$I$19:$I$30,Lookups!$J$19:$J$30,0)) | R12: 50000 | S12: =IF(Table13[[#This Row],[Life Cover Amount]]="",0,Table2[[#This Row],[Life Premium]]) -> 0 | T12: =IF(Table13[[#This Row],[Funeral Cover Amount]]=0,0,Table2[[#This Row],[Funeral Premium]]) -> 118.15 | U12: =IF(AND(Table13[[#This Row],[Life Cover Amount]]="",Table13[[#This Row],[Funeral Cover Amount]]=""),0,onboarding_calcs!AA12) -> 118.15 | BF12: =IF(Table2[[#This Row],[Upper bound for age]]=FALSE,"Check Date of Birth or Commencement Date", IF(Table2[[#This Row],[Upper bound for age]]="Max age","Check Max Entry Age", IF(AND(Table13[[#This Row],[Member Type]]="Child",Table2[[#This Row],[Age Next Birthday]]>21),"Change Member Type to Extended", IFERROR(IF(OR(Table13[[#This Row],[Product Option]]="My Value Plus Life",Table13[[#This Row],[Member Type]]="Beneficiary"),"Not applicable", IF(AND(Table13[[#This Row],[Member Type]],Table13[[#This Row],[Product Option]]="My Value Plus Life & Funeral")="Main Member","Any amount from R10,000 to R150,000", IF(AND(OR(Table13[[#This Row],[Member Type]]="Spouse",Table13[[#This Row],[Member Type]]="Child"),Table13[[#This Row],[Product Option]]="My Value Plus Life & Funeral"),Table2[[#This Row],[Validation check for Funeral Cover Amount]], IF(AND(OR(Table13[[#This Row],[Member Type]]="Extended",Table13[[#This Row],[Member Type]]="Parent"),Table13[[#This Row],[Product Option]]="My Value Plus Life & Funeral"),"Any amount from R10,000 to "&TEXT(Table2[[#This Row],[Validation check for Funeral Cover Amount]],"R#,##0"), IF(Table13[[#This Row],[Member Type]]="","", ))))),"Check Date of Birth or Commencement Date")))) -> Not applicable
P13: =IF(OR(Table13[[#This Row],[Annual Increase Option]]="No increase",Table13[[#This Row],[Annual Increase Option]]=""),"",_xlfn.XLOOKUP(MONTH(Table13[[#This Row],[Commencement Date]]),Lookups!$I$19:$I$30,Lookups!$J$19:$J$30,0)) | S13: =IF(Table13[[#This Row],[Life Cover Amount]]="",0,Table2[[#This Row],[Life Premium]]) -> 0 | T13: =IF(Table13[[#This Row],[Funeral Cover Amount]]=0,0,Table2[[#This Row],[Funeral Premium]]) -> 0 | U13: =IF(AND(Table13[[#This Row],[Life Cover Amount]]="",Table13[[#This Row],[Funeral Cover Amount]]=""),0,onboarding_calcs!AA13) -> 0 | BF13: =IF(Table2[[#This Row],[Upper bound for age]]=FALSE,"Check Date of Birth or Commencement Date", IF(Table2[[#This Row],[Upper bound for age]]="Max age","Check Max Entry Age", IF(AND(Table13[[#This Row],[Member Type]]="Child",Table2[[#This Row],[Age Next Birthday]]>21),"Change Member Type to Extended", IFERROR(IF(OR(Table13[[#This Row],[Product Option]]="My Value Plus Life",Table13[[#This Row],[Member Type]]="Beneficiary"),"Not applicable", IF(AND(Table13[[#This Row],[Member Type]],Table13[[#This Row],[Product Option]]="My Value Plus Life & Funeral")="Main Member","Any amount from R10,000 to R150,000", IF(AND(OR(Table13[[#This Row],[Member Type]]="Spouse",Table13[[#This Row],[Member Type]]="Child"),Table13[[#This Row],[Product Option]]="My Value Plus Life & Funeral"),Table2[[#This Row],[Validation check for Funeral Cover Amount]], IF(AND(OR(Table13[[#This Row],[Member Type]]="Extended",Table13[[#This Row],[Member Type]]="Parent"),Table13[[#This Row],[Product Option]]="My Value Plus Life & Funeral"),"Any amount from R10,000 to "&TEXT(Table2[[#This Row],[Validation check for Funeral Cover Amount]],"R#,##0"), IF(Table13[[#This Row],[Member Type]]="","", ))))),"Check Date of Birth or Commencement Date"))))
P14: =IF(OR(Table13[[#This Row],[Annual Increase Option]]="No increase",Table13[[#This Row],[Annual Increase Option]]=""),"",_xlfn.XLOOKUP(MONTH(Table13[[#This Row],[Commencement Date]]),Lookups!$I$19:$I$30,Lookups!$J$19:$J$30,0)) | S14: =IF(Table13[[#This Row],[Life Cover Amount]]="",0,Table2[[#This Row],[Life Premium]]) -> 0 | T14: =IF(Table13[[#This Row],[Funeral Cover Amount]]=0,0,Table2[[#This Row],[Funeral Premium]]) -> 0 | U14: =IF(AND(Table13[[#This Row],[Life Cover Amount]]="",Table13[[#This Row],[Funeral Cover Amount]]=""),0,onboarding_calcs!AA14) -> 0 | BF14: =IF(Table2[[#This Row],[Upper bound for age]]=FALSE,"Check Date of Birth or Commencement Date", IF(Table2[[#This Row],[Upper bound for age]]="Max age","Check Max Entry Age", IF(AND(Table13[[#This Row],[Member Type]]="Child",Table2[[#This Row],[Age Next Birthday]]>21),"Change Member Type to Extended", IFERROR(IF(OR(Table13[[#This Row],[Product Option]]="My Value Plus Life",Table13[[#This Row],[Member Type]]="Beneficiary"),"Not applicable", IF(AND(Table13[[#This Row],[Member Type]],Table13[[#This Row],[Product Option]]="My Value Plus Life & Funeral")="Main Member","Any amount from R10,000 to R150,000", IF(AND(OR(Table13[[#This Row],[Member Type]]="Spouse",Table13[[#This Row],[Member Type]]="Child"),Table13[[#This Row],[Product Option]]="My Value Plus Life & Funeral"),Table2[[#This Row],[Validation check for Funeral Cover Amount]], IF(AND(OR(Table13[[#This Row],[Member Type]]="Extended",Table13[[#This Row],[Member Type]]="Parent"),Table13[[#This Row],[Product Option]]="My Value Plus Life & Funeral"),"Any amount from R10,000 to "&TEXT(Table2[[#This Row],[Validation check for Funeral Cover Amount]],"R#,##0"), IF(Table13[[#This Row],[Member Type]]="","", ))))),"Check Date of Birth or Commencement Date"))))
P15: =IF(OR(Table13[[#This Row],[Annual Increase Option]]="No increase",Table13[[#This Row],[Annual Increase Option]]=""),"",_xlfn.XLOOKUP(MONTH(Table13[[#This Row],[Commencement Date]]),Lookups!$I$19:$I$30,Lookups!$J$19:$J$30,0)) | S15: =IF(Table13[[#This Row],[Life Cover Amount]]="",0,Table2[[#This Row],[Life Premium]]) -> 0 | T15: =IF(Table13[[#This Row],[Funeral Cover Amount]]=0,0,Table2[[#This Row],[Funeral Premium]]) -> 0 | U15: =IF(AND(Table13[[#This Row],[Life Cover Amount]]="",Table13[[#This Row],[Funeral Cover Amount]]=""),0,onboarding_calcs!AA15) -> 0 | BF15: =IF(Table2[[#This Row],[Upper bound for age]]=FALSE,"Check Date of Birth or Commencement Date", IF(Table2[[#This Row],[Upper bound for age]]="Max age","Check Max Entry Age", IF(AND(Table13[[#This Row],[Member Type]]="Child",Table2[[#This Row],[Age Next Birthday]]>21),"Change Member Type to Extended", IFERROR(IF(OR(Table13[[#This Row],[Product Option]]="My Value Plus Life",Table13[[#This Row],[Member Type]]="Beneficiary"),"Not applicable", IF(AND(Table13[[#This Row],[Member Type]],Table13[[#This Row],[Product Option]]="My Value Plus Life & Funeral")="Main Member","Any amount from R10,000 to R150,000", IF(AND(OR(Table13[[#This Row],[Member Type]]="Spouse",Table13[[#This Row],[Member Type]]="Child"),Table13[[#This Row],[Product Option]]="My Value Plus Life & Funeral"),Table2[[#This Row],[Validation check for Funeral Cover Amount]], IF(AND(OR(Table13[[#This Row],[Member Type]]="Extended",Table13[[#This Row],[Member Type]]="Parent"),Table13[[#This Row],[Product Option]]="My Value Plus Life & Funeral"),"Any amount from R10,000 to "&TEXT(Table2[[#This Row],[Validation check for Funeral Cover Amount]],"R#,##0"), IF(Table13[[#This Row],[Member Type]]="","", ))))),"Check Date of Birth or Commencement Date"))))
P16: =IF(OR(Table13[[#This Row],[Annual Increase Option]]="No increase",Table13[[#This Row],[Annual Increase Option]]=""),"",_xlfn.XLOOKUP(MONTH(Table13[[#This Row],[Commencement Date]]),Lookups!$I$19:$I$30,Lookups!$J$19:$J$30,0)) | S16: =IF(Table13[[#This Row],[Life Cover Amount]]="",0,Table2[[#This Row],[Life Premium]]) -> 0 | T16: =IF(Table13[[#This Row],[Funeral Cover Amount]]=0,0,Table2[[#This Row],[Funeral Premium]]) -> 0 | U16: =IF(AND(Table13[[#This Row],[Life Cover Amount]]="",Table13[[#This Row],[Funeral Cover Amount]]=""),0,onboarding_calcs!AA16) -> 0 | BF16: =IF(Table2[[#This Row],[Upper bound for age]]=FALSE,"Check Date of Birth or Commencement Date", IF(Table2[[#This Row],[Upper bound for age]]="Max age","Check Max Entry Age", IF(AND(Table13[[#This Row],[Member Type]]="Child",Table2[[#This Row],[Age Next Birthday]]>21),"Change Member Type to Extended", IFERROR(IF(OR(Table13[[#This Row],[Product Option]]="My Value Plus Life",Table13[[#This Row],[Member Type]]="Beneficiary"),"Not applicable", IF(AND(Table13[[#This Row],[Member Type]],Table13[[#This Row],[Product Option]]="My Value Plus Life & Funeral")="Main Member","Any amount from R10,000 to R150,000", IF(AND(OR(Table13[[#This Row],[Member Type]]="Spouse",Table13[[#This Row],[Member Type]]="Child"),Table13[[#This Row],[Product Option]]="My Value Plus Life & Funeral"),Table2[[#This Row],[Validation check for Funeral Cover Amount]], IF(AND(OR(Table13[[#This Row],[Member Type]]="Extended",Table13[[#This Row],[Member Type]]="Parent"),Table13[[#This Row],[Product Option]]="My Value Plus Life & Funeral"),"Any amount from R10,000 to "&TEXT(Table2[[#This Row],[Validation check for Funeral Cover Amount]],"R#,##0"), IF(Table13[[#This Row],[Member Type]]="","", ))))),"Check Date of Birth or Commencement Date"))))
P17: =IF(OR(Table13[[#This Row],[Annual Increase Option]]="No increase",Table13[[#This Row],[Annual Increase Option]]=""),"",_xlfn.XLOOKUP(MONTH(Table13[[#This Row],[Commencement Date]]),Lookups!$I$19:$I$30,Lookups!$J$19:$J$30,0)) | S17: =IF(Table13[[#This Row],[Life Cover Amount]]="",0,Table2[[#This Row],[Life Premium]]) -> 0 | T17: =IF(Table13[[#This Row],[Funeral Cover Amount]]=0,0,Table2[[#This Row],[Funeral Premium]]) -> 0 | U17: =IF(AND(Table13[[#This Row],[Life Cover Amount]]="",Table13[[#This Row],[Funeral Cover Amount]]=""),0,onboarding_calcs!AA17) -> 0 | BF17: =IF(Table2[[#This Row],[Upper bound for age]]=FALSE,"Check Date of Birth or Commencement Date", IF(Table2[[#This Row],[Upper bound for age]]="Max age","Check Max Entry Age", IF(AND(Table13[[#This Row],[Member Type]]="Child",Table2[[#This Row],[Age Next Birthday]]>21),"Change Member Type to Extended", IFERROR(IF(OR(Table13[[#This Row],[Product Option]]="My Value Plus Life",Table13[[#This Row],[Member Type]]="Beneficiary"),"Not applicable", IF(AND(Table13[[#This Row],[Member Type]],Table13[[#This Row],[Product Option]]="My Value Plus Life & Funeral")="Main Member","Any amount from R10,000 to R150,000", IF(AND(OR(Table13[[#This Row],[Member Type]]="Spouse",Table13[[#This Row],[Member Type]]="Child"),Table13[[#This Row],[Product Option]]="My Value Plus Life & Funeral"),Table2[[#This Row],[Validation check for Funeral Cover Amount]], IF(AND(OR(Table13[[#This Row],[Member Type]]="Extended",Table13[[#This Row],[Member Type]]="Parent"),Table13[[#This Row],[Product Option]]="My Value Plus Life & Funeral"),"Any amount from R10,000 to "&TEXT(Table2[[#This Row],[Validation check for Funeral Cover Amount]],"R#,##0"), IF(Table13[[#This Row],[Member Type]]="","", ))))),"Check Date of Birth or Commencement Date"))))
P18: =IF(OR(Table13[[#This Row],[Annual Increase Option]]="No increase",Table13[[#This Row],[Annual Increase Option]]=""),"",_xlfn.XLOOKUP(MONTH(Table13[[#This Row],[Commencement Date]]),Lookups!$I$19:$I$30,Lookups!$J$19:$J$30,0)) | S18: =IF(Table13[[#This Row],[Life Cover Amount]]="",0,Table2[[#This Row],[Life Premium]]) -> 0 | T18: =IF(Table13[[#This Row],[Funeral Cover Amount]]=0,0,Table2[[#This Row],[Funeral Premium]]) -> 0 | U18: =IF(AND(Table13[[#This Row],[Life Cover Amount]]="",Table13[[#This Row],[Funeral Cover Amount]]=""),0,onboarding_calcs!AA18) -> 0 | BF18: =IF(Table2[[#This Row],[Upper bound for age]]=FALSE,"Check Date of Birth or Commencement Date", IF(Table2[[#This Row],[Upper bound for age]]="Max age","Check Max Entry Age", IF(AND(Table13[[#This Row],[Member Type]]="Child",Table2[[#This Row],[Age Next Birthday]]>21),"Change Member Type to Extended", IFERROR(IF(OR(Table13[[#This Row],[Product Option]]="My Value Plus Life",Table13[[#This Row],[Member Type]]="Beneficiary"),"Not applicable", IF(AND(Table13[[#This Row],[Member Type]],Table13[[#This Row],[Product Option]]="My Value Plus Life & Funeral")="Main Member","Any amount from R10,000 to R150,000", IF(AND(OR(Table13[[#This Row],[Member Type]]="Spouse",Table13[[#This Row],[Member Type]]="Child"),Table13[[#This Row],[Product Option]]="My Value Plus Life & Funeral"),Table2[[#This Row],[Validation check for Funeral Cover Amount]], IF(AND(OR(Table13[[#This Row],[Member Type]]="Extended",Table13[[#This Row],[Member Type]]="Parent"),Table13[[#This Row],[Product Option]]="My Value Plus Life & Funeral"),"Any amount from R10,000 to "&TEXT(Table2[[#This Row],[Validation check for Funeral Cover Amount]],"R#,##0"), IF(Table13[[#This Row],[Member Type]]="","", ))))),"Check Date of Birth or Commencement Date"))))
P19: =IF(OR(Table13[[#This Row],[Annual Increase Option]]="No increase",Table13[[#This Row],[Annual Increase Option]]=""),"",_xlfn.XLOOKUP(MONTH(Table13[[#This Row],[Commencement Date]]),Lookups!$I$19:$I$30,Lookups!$J$19:$J$30,0)) | S19: =IF(Table13[[#This Row],[Life Cover Amount]]="",0,Table2[[#This Row],[Life Premium]]) -> 0 | T19: =IF(Table13[[#This Row],[Funeral Cover Amount]]=0,0,Table2[[#This Row],[Funeral Premium]]) -> 0 | U19: =IF(AND(Table13[[#This Row],[Life Cover Amount]]="",Table13[[#This Row],[Funeral Cover Amount]]=""),0,onboarding_calcs!AA19) -> 0 | BF19: =IF(Table2[[#This Row],[Upper bound for age]]=FALSE,"Check Date of Birth or Commencement Date", IF(Table2[[#This Row],[Upper bound for age]]="Max age","Check Max Entry Age", IF(AND(Table13[[#This Row],[Member Type]]="Child",Table2[[#This Row],[Age Next Birthday]]>21),"Change Member Type to Extended", IFERROR(IF(OR(Table13[[#This Row],[Product Option]]="My Value Plus Life",Table13[[#This Row],[Member Type]]="Beneficiary"),"Not applicable", IF(AND(Table13[[#This Row],[Member Type]],Table13[[#This Row],[Product Option]]="My Value Plus Life & Funeral")="Main Member","Any amount from R10,000 to R150,000", IF(AND(OR(Table13[[#This Row],[Member Type]]="Spouse",Table13[[#This Row],[Member Type]]="Child"),Table13[[#This Row],[Product Option]]="My Value Plus Life & Funeral"),Table2[[#This Row],[Validation check for Funeral Cover Amount]], IF(AND(OR(Table13[[#This Row],[Member Type]]="Extended",Table13[[#This Row],[Member Type]]="Parent"),Table13[[#This Row],[Product Option]]="My Value Plus Life & Funeral"),"Any amount from R10,000 to "&TEXT(Table2[[#This Row],[Validation check for Funeral Cover Amount]],"R#,##0"), IF(Table13[[#This Row],[Member Type]]="","", ))))),"Check Date of Birth or Commencement Date"))))
P20: =IF(OR(Table13[[#This Row],[Annual Increase Option]]="No increase",Table13[[#This Row],[Annual Increase Option]]=""),"",_xlfn.XLOOKUP(MONTH(Table13[[#This Row],[Commencement Date]]),Lookups!$I$19:$I$30,Lookups!$J$19:$J$30,0)) | S20: =IF(Table13[[#This Row],[Life Cover Amount]]="",0,Table2[[#This Row],[Life Premium]]) -> 0 | T20: =IF(Table13[[#This Row],[Funeral Cover Amount]]=0,0,Table2[[#This Row],[Funeral Premium]]) -> 0 | U20: =IF(AND(Table13[[#This Row],[Life Cover Amount]]="",Table13[[#This Row],[Funeral Cover Amount]]=""),0,onboarding_calcs!AA20) -> 0 | BF20: =IF(Table2[[#This Row],[Upper bound for age]]=FALSE,"Check Date of Birth or Commencement Date", IF(Table2[[#This Row],[Upper bound for age]]="Max age","Check Max Entry Age", IF(AND(Table13[[#This Row],[Member Type]]="Child",Table2[[#This Row],[Age Next Birthday]]>21),"Change Member Type to Extended", IFERROR(IF(OR(Table13[[#This Row],[Product Option]]="My Value Plus Life",Table13[[#This Row],[Member Type]]="Beneficiary"),"Not applicable", IF(AND(Table13[[#This Row],[Member Type]],Table13[[#This Row],[Product Option]]="My Value Plus Life & Funeral")="Main Member","Any amount from R10,000 to R150,000", IF(AND(OR(Table13[[#This Row],[Member Type]]="Spouse",Table13[[#This Row],[Member Type]]="Child"),Table13[[#This Row],[Product Option]]="My Value Plus Life & Funeral"),Table2[[#This Row],[Validation check for Funeral Cover Amount]], IF(AND(OR(Table13[[#This Row],[Member Type]]="Extended",Table13[[#This Row],[Member Type]]="Parent"),Table13[[#This Row],[Product Option]]="My Value Plus Life & Funeral"),"Any amount from R10,000 to "&TEXT(Table2[[#This Row],[Validation check for Funeral Cover Amount]],"R#,##0"), IF(Table13[[#This Row],[Member Type]]="","", ))))),"Check Date of Birth or Commencement Date"))))
P21: =IF(OR(Table13[[#This Row],[Annual Increase Option]]="No increase",Table13[[#This Row],[Annual Increase Option]]=""),"",_xlfn.XLOOKUP(MONTH(Table13[[#This Row],[Commencement Date]]),Lookups!$I$19:$I$30,Lookups!$J$19:$J$30,0)) | S21: =IF(Table13[[#This Row],[Life Cover Amount]]="",0,Table2[[#This Row],[Life Premium]]) -> 0 | T21: =IF(Table13[[#This Row],[Funeral Cover Amount]]=0,0,Table2[[#This Row],[Funeral Premium]]) -> 0 | U21: =IF(AND(Table13[[#This Row],[Life Cover Amount]]="",Table13[[#This Row],[Funeral Cover Amount]]=""),0,onboarding_calcs!AA21) -> 0 | BF21: =IF(Table2[[#This Row],[Upper bound for age]]=FALSE,"Check Date of Birth or Commencement Date", IF(Table2[[#This Row],[Upper bound for age]]="Max age","Check Max Entry Age", IF(AND(Table13[[#This Row],[Member Type]]="Child",Table2[[#This Row],[Age Next Birthday]]>21),"Change Member Type to Extended", IFERROR(IF(OR(Table13[[#This Row],[Product Option]]="My Value Plus Life",Table13[[#This Row],[Member Type]]="Beneficiary"),"Not applicable", IF(AND(Table13[[#This Row],[Member Type]],Table13[[#This Row],[Product Option]]="My Value Plus Life & Funeral")="Main Member","Any amount from R10,000 to R150,000", IF(AND(OR(Table13[[#This Row],[Member Type]]="Spouse",Table13[[#This Row],[Member Type]]="Child"),Table13[[#This Row],[Product Option]]="My Value Plus Life & Funeral"),Table2[[#This Row],[Validation check for Funeral Cover Amount]], IF(AND(OR(Table13[[#This Row],[Member Type]]="Extended",Table13[[#This Row],[Member Type]]="Parent"),Table13[[#This Row],[Product Option]]="My Value Plus Life & Funeral"),"Any amount from R10,000 to "&TEXT(Table2[[#This Row],[Validation check for Funeral Cover Amount]],"R#,##0"), IF(Table13[[#This Row],[Member Type]]="","", ))))),"Check Date of Birth or Commencement Date"))))
P22: =IF(OR(Table13[[#This Row],[Annual Increase Option]]="No increase",Table13[[#This Row],[Annual Increase Option]]=""),"",_xlfn.XLOOKUP(MONTH(Table13[[#This Row],[Commencement Date]]),Lookups!$I$19:$I$30,Lookups!$J$19:$J$30,0)) | S22: =IF(Table13[[#This Row],[Life Cover Amount]]="",0,Table2[[#This Row],[Life Premium]]) -> 0 | T22: =IF(Table13[[#This Row],[Funeral Cover Amount]]=0,0,Table2[[#This Row],[Funeral Premium]]) -> 0 | U22: =IF(AND(Table13[[#This Row],[Life Cover Amount]]="",Table13[[#This Row],[Funeral Cover Amount]]=""),0,onboarding_calcs!AA22) -> 0 | BF22: =IF(Table2[[#This Row],[Upper bound for age]]=FALSE,"Check Date of Birth or Commencement Date", IF(Table2[[#This Row],[Upper bound for age]]="Max age","Check Max Entry Age", IF(AND(Table13[[#This Row],[Member Type]]="Child",Table2[[#This Row],[Age Next Birthday]]>21),"Change Member Type to Extended", IFERROR(IF(OR(Table13[[#This Row],[Product Option]]="My Value Plus Life",Table13[[#This Row],[Member Type]]="Beneficiary"),"Not applicable", IF(AND(Table13[[#This Row],[Member Type]],Table13[[#This Row],[Product Option]]="My Value Plus Life & Funeral")="Main Member","Any amount from R10,000 to R150,000", IF(AND(OR(Table13[[#This Row],[Member Type]]="Spouse",Table13[[#This Row],[Member Type]]="Child"),Table13[[#This Row],[Product Option]]="My Value Plus Life & Funeral"),Table2[[#This Row],[Validation check for Funeral Cover Amount]], IF(AND(OR(Table13[[#This Row],[Member Type]]="Extended",Table13[[#This Row],[Member Type]]="Parent"),Table13[[#This Row],[Product Option]]="My Value Plus Life & Funeral"),"Any amount from R10,000 to "&TEXT(Table2[[#This Row],[Validation check for Funeral Cover Amount]],"R#,##0"), IF(Table13[[#This Row],[Member Type]]="","", ))))),"Check Date of Birth or Commencement Date"))))
P23: =IF(OR(Table13[[#This Row],[Annual Increase Option]]="No increase",Table13[[#This Row],[Annual Increase Option]]=""),"",_xlfn.XLOOKUP(MONTH(Table13[[#This Row],[Commencement Date]]),Lookups!$I$19:$I$30,Lookups!$J$19:$J$30,0)) | S23: =IF(Table13[[#This Row],[Life Cover Amount]]="",0,Table2[[#This Row],[Life Premium]]) -> 0 | T23: =IF(Table13[[#This Row],[Funeral Cover Amount]]=0,0,Table2[[#This Row],[Funeral Premium]]) -> 0 | U23: =IF(AND(Table13[[#This Row],[Life Cover Amount]]="",Table13[[#This Row],[Funeral Cover Amount]]=""),0,onboarding_calcs!AA23) -> 0 | BF23: =IF(Table2[[#This Row],[Upper bound for age]]=FALSE,"Check Date of Birth or Commencement Date", IF(Table2[[#This Row],[Upper bound for age]]="Max age","Check Max Entry Age", IF(AND(Table13[[#This Row],[Member Type]]="Child",Table2[[#This Row],[Age Next Birthday]]>21),"Change Member Type to Extended", IFERROR(IF(OR(Table13[[#This Row],[Product Option]]="My Value Plus Life",Table13[[#This Row],[Member Type]]="Beneficiary"),"Not applicable", IF(AND(Table13[[#This Row],[Member Type]],Table13[[#This Row],[Product Option]]="My Value Plus Life & Funeral")="Main Member","Any amount from R10,000 to R150,000", IF(AND(OR(Table13[[#This Row],[Member Type]]="Spouse",Table13[[#This Row],[Member Type]]="Child"),Table13[[#This Row],[Product Option]]="My Value Plus Life & Funeral"),Table2[[#This Row],[Validation check for Funeral Cover Amount]], IF(AND(OR(Table13[[#This Row],[Member Type]]="Extended",Table13[[#This Row],[Member Type]]="Parent"),Table13[[#This Row],[Product Option]]="My Value Plus Life & Funeral"),"Any amount from R10,000 to "&TEXT(Table2[[#This Row],[Validation check for Funeral Cover Amount]],"R#,##0"), IF(Table13[[#This Row],[Member Type]]="","", ))))),"Check Date of Birth or Commencement Date"))))
P24: =IF(OR(Table13[[#This Row],[Annual Increase Option]]="No increase",Table13[[#This Row],[Annual Increase Option]]=""),"",_xlfn.XLOOKUP(MONTH(Table13[[#This Row],[Commencement Date]]),Lookups!$I$19:$I$30,Lookups!$J$19:$J$30,0)) | S24: =IF(Table13[[#This Row],[Life Cover Amount]]="",0,Table2[[#This Row],[Life Premium]]) -> 0 | T24: =IF(Table13[[#This Row],[Funeral Cover Amount]]=0,0,Table2[[#This Row],[Funeral Premium]]) -> 0 | U24: =IF(AND(Table13[[#This Row],[Life Cover Amount]]="",Table13[[#This Row],[Funeral Cover Amount]]=""),0,onboarding_calcs!AA24) -> 0 | BF24: =IF(Table2[[#This Row],[Upper bound for age]]=FALSE,"Check Date of Birth or Commencement Date", IF(Table2[[#This Row],[Upper bound for age]]="Max age","Check Max Entry Age", IF(AND(Table13[[#This Row],[Member Type]]="Child",Table2[[#This Row],[Age Next Birthday]]>21),"Change Member Type to Extended", IFERROR(IF(OR(Table13[[#This Row],[Product Option]]="My Value Plus Life",Table13[[#This Row],[Member Type]]="Beneficiary"),"Not applicable", IF(AND(Table13[[#This Row],[Member Type]],Table13[[#This Row],[Product Option]]="My Value Plus Life & Funeral")="Main Member","Any amount from R10,000 to R150,000", IF(AND(OR(Table13[[#This Row],[Member Type]]="Spouse",Table13[[#This Row],[Member Type]]="Child"),Table13[[#This Row],[Product Option]]="My Value Plus Life & Funeral"),Table2[[#This Row],[Validation check for Funeral Cover Amount]], IF(AND(OR(Table13[[#This Row],[Member Type]]="Extended",Table13[[#This Row],[Member Type]]="Parent"),Table13[[#This Row],[Product Option]]="My Value Plus Life & Funeral"),"Any amount from R10,000 to "&TEXT(Table2[[#This Row],[Validation check for Funeral Cover Amount]],"R#,##0"), IF(Table13[[#This Row],[Member Type]]="","", ))))),"Check Date of Birth or Commencement Date"))))
... P650: =IF(OR(Table13[[#This Row],[Annual Increase Option]]="No increase",Table13[[#This Row],[Annual Increase Option]]=""),"",_xlfn.XLOOKUP(MONTH(Table13[[#This Row],[Commencement Date]]),Lookups!$I$19:$I$30,Lookups!$J$19:$J$30,0)) | S650: =IF(Table13[[#This Row],[Life Cover Amount]]="",0,Table2[[#This Row],[Life Premium]]) -> 0 | T650: =IF(Table13[[#This Row],[Funeral Cover Amount]]=0,0,Table2[[#This Row],[Funeral Premium]]) -> 0 | U650: =IF(AND(Table13[[#This Row],[Life Cover Amount]]="",Table13[[#This Row],[Funeral Cover Amount]]=""),0,onboarding_calcs!AA650) -> 0 | BF650: =IF(Table2[[#This Row],[Upper bound for age]]=FALSE,"Check Date of Birth or Commencement Date", IF(Table2[[#This Row],[Upper bound for age]]="Max age","Check Max Entry Age", IF(AND(Table13[[#This Row],[Member Type]]="Child",Table2[[#This Row],[Age Next Birthday]]>21),"Change Member Type to Extended", IFERROR(IF(OR(Table13[[#This Row],[Product Option]]="My Value Plus Life",Table13[[#This Row],[Member Type]]="Beneficiary"),"Not applicable", IF(AND(Table13[[#This Row],[Member Type]],Table13[[#This Row],[Product Option]]="My Value Plus Life & Funeral")="Main Member","Any amount from R10,000 to R150,000", IF(AND(OR(Table13[[#This Row],[Member Type]]="Spouse",Table13[[#This Row],[Member Type]]="Child"),Table13[[#This Row],[Product Option]]="My Value Plus Life & Funeral"),Table2[[#This Row],[Validation check for Funeral Cover Amount]], IF(AND(OR(Table13[[#This Row],[Member Type]]="Extended",Table13[[#This Row],[Member Type]]="Parent"),Table13[[#This Row],[Product Option]]="My Value Plus Life & Funeral"),"Any amount from R10,000 to "&TEXT(Table2[[#This Row],[Validation check for Funeral Cover Amount]],"R#,##0"), IF(Table13[[#This Row],[Member Type]]="","", ))))),"Check Date of Birth or Commencement Date"))))

Sheet onboarding_calcs
A4: Member Type | B4: Main Member Link ID | C4: ID Number | D4: Date Of Birth | E4: Commencement Date | F4: Age Next Birthday | G4: Upper bound for age | H4: Product Option | I4: Table Lookup for Life Cover | J4: Column Index (Life) | K4: Life Fixed Rate | L4: Life Rate per 1,000 | M4: Life Premium | N4: Benefit Name | O4: Table Lookup for Funeral | P4: Column Index (Funeral) | Q4: Funeral Fixed Rate | R4: Funeral Rate per 1,000 | S4: Funeral Premium | T4: Premium Waiver | U4: VAPs Options | V4: Annual Increase Option | W4: Life Cover Amount | X4: Funeral Cover Amount | Y4: Validation check for Life Cover Amount | Z4: Validation check for Funeral Cover Amount | AA4: Premium (excl. VAPs) | AC4: Product Option1 | AD4: Product Option2 | AE4: Benefit Option1 | AF4: Benefit Option2 | AG4: Benefit Option3 | AH4: Benefit Option4 | AI4: Premium Waiver Selection | AJ4: Member Count | AK4: Member Type Count
